Workbook

Sheet Numbers
A1: Financing/Initial Costs | D1: Key Numbers
A3: Price | B3: 75000 | D3: Loan Amount | E3: =B3*B6 -> 71250
A4: Annual Interest Rate (nominal) | B4: 0.0395 | D4: Monthly P+I | E4: =E3*(B4/12)/(1-1/(1+B4/12)^(12*B5)) -> 338.10778
A5: Loan Term (Years) | B5: 30 | D5: Init Monthly Int | E5: =(B4/12)*E3 -> 234.53125
A6: Percent to be Financed | B6: 0.95 | D6: Init Monthly Princ | E6: =E4-E5 -> 103.57653
A7: Closing Costs above Down Payment | B7: 3000 | D7: Monthly PMI | E7: =(B9/12)*E3 -> 26.71875
A8: Improvements Before Renting | B8: 5000 | D8: Init Monthly Insurance | E8: =B17*B3/12 -> 91.666667
A9: Annual PMI Rate | B9: 0.0045 | D9: Init Monthly Prop Tax | E9: =B18*B3/12 -> 97
A10: % of Princ Paid for PMI Expiration | B10: 0.2 | D10: Total Monthly Mtg Pmt | E10: =E4+E7+E8+E9 -> 553.4932
A11: Months Until Rented | B11: 2
A13: Income/Expenses | D13: Adjusted Basis | E13: =B3+B7+B8 -> 83000
D14: Yearly Depreciation | E14: =B34*(B32*B3+B7+B8) -> 2472.7273
A15: Initial Monthly Rent | B15: 1200 | D15: Init Gross Yearly Income | E15: =12*(1-B33)*B15 -> 12960
A16: Init Mthly Maintenance (Occupied) | B16: 100 | D16: Init Taxable Yearly Income | E16: =E15-12*(E10+(1-B33)*B16+B33*B19)+E4*(1/(1+B4/12)^(B5*12-12))*(1-1/(1+B4/12)^12)/(B4/12)-E14 -> 3947.0235
A17: Insurance Rate (yearly) | B17: =1100/75000 -> 0.014666667 | D17: Init Pre-tax Income | E17: =E15-12*(E10+(1-B33)*B16+B33*B19) -> 5154.0816
A18: Property Tax Rate (yearly) | B18: =1164/75000 -> 0.01552 | D18: Init Yearly Income Taxes | E18: =E16*B35 -> 986.75587
A19: Monthly Costs when Unoccupied | B19: 70
A21: Sale Costs/Percentages | D21: Cap Rate | E21: =12*(B15*(1-B33)-(E8+E9+B16*(1-B33)+B19*B33))/B3 -> 0.12709333
D22: Lithmus | E22: =12*(B15-(E8+E9))/B3 -> 0.16181333
A23: Real Estate Commissions | B23: 0.06 | D23: Total Initial Investment | E23: =(1-B6)*B3+B7+B8 -> 11750
A24: Additional Sale Costs | B24: 3000 | D24: Init Net Yearly Income | E24: =E17-E18 -> 4167.3258
A25: Capital Gains Rate | B25: 0.15 | D25: Init Months to Break Even | E25: =(B35*(-12*E10-12*B19+E4*(1/(1+B4/12)^(B5*12-12))*(1-1/(1+B4/12)^12)/(B4/12)-E14)+12*E10+12*B19)/((B35-1)*(B16-B15-B19)) -> 6.0509108
A26: Depreciation Recapture Rate | B26: 0.25
D27: Initial Yearly Cash ROI | E27: =E24/E23 -> 0.35466602
A28: Other Rates | D28: Initial Yearly Principal ROI | E28: =E4*(1/(1+B4/12)^(B5*12-12))*(1-1/(1+B4/12)^12)/(B4/12)/E23 -> 0.10771652
A30: Annual % Rent/Expense Increase | B30: 0.02
A31: Annual Real Estate Appr Rate | B31: 0.03
A32: Percentage of Property Depreciable | B32: 0.8
A33: Vacancy Rate | B33: 0.1
A34: Yearly Depreciation Rate | B34: =1/27.5 -> 0.036363636
A35: Tax Rate (Federal + State) | B35: 0.25

Sheet 30 Year IRR
A1: Year | B1: Interest Paid | C1: Principal Paid | D1: PMI Paid | E1: Gross Income | F1: Income Taxes | G1: Net Cash Flow
A3: 0 | G3: =-Numbers!E23 -> -11750
A4: 1 | B4: =IF(A4<=Numbers!$B$5,Numbers!$E$4*(12*'30 Year IRR'!A4-1/(1+Numbers!$B$4/12)^(Numbers!$B$5*12-12*'30 Year IRR'!A4)*(1-1/(1+Numbers!$B$4/12)^(12*'30 Year IRR'!A4))/(Numbers!$B$4/12))-Numbers!$E$4*(12*'30 Year IRR'!A3-1/(1+Numbers!$B$4/12)^(Numbers!$B$5*12-12*'30 Year IRR'!A3)*(1-1/(1+Numbers!$B$4/12)^(12*'30 Year IRR'!A3))/(Numbers!$B$4/12)),0) -> 2791.6243 | C4: =IF(A4<=Numbers!$B$5,Numbers!$E$4*(1/(1+Numbers!$B$4/12))^(12*Numbers!$B$5-12*'30 Year IRR'!A4)*(1-1/(1+Numbers!$B$4/12)^(12*'30 Year IRR'!A4))/(Numbers!$B$4/12)-Numbers!$E$4*(1/(1+Numbers!$B$4/12))^(12*Numbers!$B$5-12*('30 Year IRR'!A4-1))*(1-1/(1+Numbers!$B$4/12)^(12*('30 Year IRR'!A4-1)))/(Numbers!$B$4/12),0) -> 1265.6691 | D4: =IF(SUM($C$3:C3)/Numbers!$E$3<Numbers!$B$10,12*Numbers!$E$7,0) -> 320.625 | E4: =12*Numbers!$B$15*(1-Numbers!$B$33)*(1+Numbers!$B$30)^('30 Year IRR'!A4-1)-('30 Year IRR'!B4+'30 Year IRR'!C4+'30 Year IRR'!D4+12*(Numbers!$E$8+Numbers!$E$9)*(1+Numbers!$B$30)^('30 Year IRR'!A4-1)+12*(1-Numbers!$B$33)*Numbers!$B$16*(1+Numbers!$B$30)^('30 Year IRR'!A4-1)+12*Numbers!$B$33*Numbers!$B$19*(1+Numbers!$B$30)^('30 Year IRR'!A4-1))-Numbers!B11*Numbers!B15 -> 2754.0816 | F4: =Numbers!$B$35*('30 Year IRR'!E4+'30 Year IRR'!C4-IF(A4<27.5,Numbers!$E$14,0)) -> 386.75587 | G4: =E4-F4 -> 2367.3258
A5: 2 | B5: =IF(A5<=Numbers!$B$5,Numbers!$E$4*(12*'30 Year IRR'!A5-1/(1+Numbers!$B$4/12)^(Numbers!$B$5*12-12*'30 Year IRR'!A5)*(1-1/(1+Numbers!$B$4/12)^(12*'30 Year IRR'!A5))/(Numbers!$B$4/12))-Numbers!$E$4*(12*'30 Year IRR'!A4-1/(1+Numbers!$B$4/12)^(Numbers!$B$5*12-12*'30 Year IRR'!A4)*(1-1/(1+Numbers!$B$4/12)^(12*'30 Year IRR'!A4))/(Numbers!$B$4/12)),0) -> 2740.7152 | C5: =IF(A5<=Numbers!$B$5,Numbers!$E$4*(1/(1+Numbers!$B$4/12))^(12*Numbers!$B$5-12*'30 Year IRR'!A5)*(1-1/(1+Numbers!$B$4/12)^(12*'30 Year IRR'!A5))/(Numbers!$B$4/12)-Numbers!$E$4*(1/(1+Numbers!$B$4/12))^(12*Numbers!$B$5-12*('30 Year IRR'!A5-1))*(1-1/(1+Numbers!$B$4/12)^(12*('30 Year IRR'!A5-1)))/(Numbers!$B$4/12),0) -> 1316.5781 | D5: =IF(SUM($C$3:C4)/Numbers!$E$3<Numbers!$B$10,12*Numbers!$E$7,0) -> 320.625 | E5: =12*Numbers!$B$15*(1-Numbers!$B$33)*(1+Numbers!$B$30)^('30 Year IRR'!A5-1)-('30 Year IRR'!B5+'30 Year IRR'!C5+'30 Year IRR'!D5+12*(Numbers!$E$8+Numbers!$E$9)*(1+Numbers!$B$30)^('30 Year IRR'!A5-1)+12*(1-Numbers!$B$33)*Numbers!$B$16*(1+Numbers!$B$30)^('30 Year IRR'!A5-1)+12*Numbers!$B$33*Numbers!$B$19*(1+Numbers!$B$30)^('30 Year IRR'!A5-1)) -> 5344.7216 | F5: =Numbers!$B$35*('30 Year IRR'!E5+'30 Year IRR'!C5-IF(A5<27.5,Numbers!$E$14,0)) -> 1047.1431 | G5: =E5-F5 -> 4297.5785
A6: 3 | B6: =IF(A6<=Numbers!$B$5,Numbers!$E$4*(12*'30 Year IRR'!A6-1/(1+Numbers!$B$4/12)^(Numbers!$B$5*12-12*'30 Year IRR'!A6)*(1-1/(1+Numbers!$B$4/12)^(12*'30 Year IRR'!A6))/(Numbers!$B$4/12))-Numbers!$E$4*(12*'30 Year IRR'!A5-1/(1+Numbers!$B$4/12)^(Numbers!$B$5*12-12*'30 Year IRR'!A5)*(1-1/(1+Numbers!$B$4/12)^(12*'30 Year IRR'!A5))/(Numbers!$B$4/12)),0) -> 2687.7585 | C6: =IF(A6<=Numbers!$B$5,Numbers!$E$4*(1/(1+Numbers!$B$4/12))^(12*Numbers!$B$5-12*'30 Year IRR'!A6)*(1-1/(1+Numbers!$B$4/12)^(12*'30 Year IRR'!A6))/(Numbers!$B$4/12)-Numbers!$E$4*(1/(1+Numbers!$B$4/12))^(12*Numbers!$B$5-12*('30 Year IRR'!A6-1))*(1-1/(1+Numbers!$B$4/12)^(12*('30 Year IRR'!A6-1)))/(Numbers!$B$4/12),0) -> 1369.5349 | D6: =IF(SUM($C$3:C5)/Numbers!$E$3<Numbers!$B$10,12*Numbers!$E$7,0) -> 320.625 | E6: =12*Numbers!$B$15*(1-Numbers!$B$33)*(1+Numbers!$B$30)^('30 Year IRR'!A6-1)-('30 Year IRR'!B6+'30 Year IRR'!C6+'30 Year IRR'!D6+12*(Numbers!$E$8+Numbers!$E$9)*(1+Numbers!$B$30)^('30 Year IRR'!A6-1)+12*(1-Numbers!$B$33)*Numbers!$B$16*(1+Numbers!$B$30)^('30 Year IRR'!A6-1)+12*Numbers!$B$33*Numbers!$B$19*(1+Numbers!$B$30)^('30 Year IRR'!A6-1)) -> 5539.1744 | F6: =Numbers!$B$35*('30 Year IRR'!E6+'30 Year IRR'!C6-IF(A6<27.5,Numbers!$E$14,0)) -> 1108.9955 | G6: =E6-F6 -> 4430.1789
A7: 4 | B7: =IF(A7<=Numbers!$B$5,Numbers!$E$4*(12*'30 Year IRR'!A7-1/(1+Numbers!$B$4/12)^(Numbers!$B$5*12-12*'30 Year IRR'!A7)*(1-1/(1+Numbers!$B$4/12)^(12*'30 Year IRR'!A7))/(Numbers!$B$4/12))-Numbers!$E$4*(12*'30 Year IRR'!A6-1/(1+Numbers!$B$4/12)^(Numbers!$B$5*12-12*'30 Year IRR'!A6)*(1-1/(1+Numbers!$B$4/12)^(12*'30 Year IRR'!A6))/(Numbers!$B$4/12)),0) -> 2632.6717 | C7: =IF(A7<=Numbers!$B$5,Numbers!$E$4*(1/(1+Numbers!$B$4/12))^(12*Numbers!$B$5-12*'30 Year IRR'!A7)*(1-1/(1+Numbers!$B$4/12)^(12*'30 Year IRR'!A7))/(Numbers!$B$4/12)-Numbers!$E$4*(1/(1+Numbers!$B$4/12))^(12*Numbers!$B$5-12*('30 Year IRR'!A7-1))*(1-1/(1+Numbers!$B$4/12)^(12*('30 Year IRR'!A7-1)))/(Numbers!$B$4/12),0) -> 1424.6217 | D7: =IF(SUM($C$3:C6)/Numbers!$E$3<Numbers!$B$10,12*Numbers!$E$7,0) -> 320.625 | E7: =12*Numbers!$B$15*(1-Numbers!$B$33)*(1+Numbers!$B$30)^('30 Year IRR'!A7-1)-('30 Year IRR'!B7+'30 Year IRR'!C7+'30 Year IRR'!D7+12*(Numbers!$E$8+Numbers!$E$9)*(1+Numbers!$B$30)^('30 Year IRR'!A7-1)+12*(1-Numbers!$B$33)*Numbers!$B$16*(1+Numbers!$B$30)^('30 Year IRR'!A7-1)+12*Numbers!$B$33*Numbers!$B$19*(1+Numbers!$B$30)^('30 Year IRR'!A7-1)) -> 5737.5163 | F7: =Numbers!$B$35*('30 Year IRR'!E7+'30 Year IRR'!C7-IF(A7<27.5,Numbers!$E$14,0)) -> 1172.3527 | G7: =E7-F7 -> 4565.1636
A8: 5 | B8: =IF(A8<=Numbers!$B$5,Numbers!$E$4*(12*'30 Year IRR'!A8-1/(1+Numbers!$B$4/12)^(Numbers!$B$5*12-12*'30 Year IRR'!A8)*(1-1/(1+Numbers!$B$4/12)^(12*'30 Year IRR'!A8))/(Numbers!$B$4/12))-Numbers!$E$4*(12*'30 Year IRR'!A7-1/(1+Numbers!$B$4/12)^(Numbers!$B$5*12-12*'30 Year IRR'!A7)*(1-1/(1+Numbers!$B$4/12)^(12*'30 Year IRR'!A7))/(Numbers!$B$4/12)),0) -> 2575.3691 | C8: =IF(A8<=Numbers!$B$5,Numbers!$E$4*(1/(1+Numbers!$B$4/12))^(12*Numbers!$B$5-12*'30 Year IRR'!A8)*(1-1/(1+Numbers!$B$4/12)^(12*'30 Year IRR'!A8))/(Numbers!$B$4/12)-Numbers!$E$4*(1/(1+Numbers!$B$4/12))^(12*Numbers!$B$5-12*('30 Year IRR'!A8-1))*(1-1/(1+Numbers!$B$4/12)^(12*('30 Year IRR'!A8-1)))/(Numbers!$B$4/12),0) -> 1481.9243 | D8: =IF(SUM($C$3:C7)/Numbers!$E$3<Numbers!$B$10,12*Numbers!$E$7,0) -> 320.625 | E8: =12*Numbers!$B$15*(1-Numbers!$B$33)*(1+Numbers!$B$30)^('30 Year IRR'!A8-1)-('30 Year IRR'!B8+'30 Year IRR'!C8+'30 Year IRR'!D8+12*(Numbers!$E$8+Numbers!$E$9)*(1+Numbers!$B$30)^('30 Year IRR'!A8-1)+12*(1-Numbers!$B$33)*Numbers!$B$16*(1+Numbers!$B$30)^('30 Year IRR'!A8-1)+12*Numbers!$B$33*Numbers!$B$19*(1+Numbers!$B$30)^('30 Year IRR'!A8-1)) -> 5939.825 | F8: =Numbers!$B$35*('30 Year IRR'!E8+'30 Year IRR'!C8-IF(A8<27.5,Numbers!$E$14,0)) -> 1237.2555 | G8: =E8-F8 -> 4702.5695
A9: 6 | B9: =IF(A9<=Numbers!$B$5,Numbers!$E$4*(12*'30 Year IRR'!A9-1/(1+Numbers!$B$4/12)^(Numbers!$B$5*12-12*'30 Year IRR'!A9)*(1-1/(1+Numbers!$B$4/12)^(12*'30 Year IRR'!A9))/(Numbers!$B$4/12))-Numbers!$E$4*(12*'30 Year IRR'!A8-1/(1+Numbers!$B$4/12)^(Numbers!$B$5*12-12*'30 Year IRR'!A8)*(1-1/(1+Numbers!$B$4/12)^(12*'30 Year IRR'!A8))/(Numbers!$B$4/12)),0) -> 2515.7616 | C9: =IF(A9<=Numbers!$B$5,Numbers!$E$4*(1/(1+Numbers!$B$4/12))^(12*Numbers!$B$5-12*'30 Year IRR'!A9)*(1-1/(1+Numbers!$B$4/12)^(12*'30 Year IRR'!A9))/(Numbers!$B$4/12)-Numbers!$E$4*(1/(1+Numbers!$B$4/12))^(12*Numbers!$B$5-12*('30 Year IRR'!A9-1))*(1-1/(1+Numbers!$B$4/12)^(12*('30 Year IRR'!A9-1)))/(Numbers!$B$4/12),0) -> 1541.5318 | D9: =IF(SUM($C$3:C8)/Numbers!$E$3<Numbers!$B$10,12*Numbers!$E$7,0) -> 320.625 | E9: =12*Numbers!$B$15*(1-Numbers!$B$33)*(1+Numbers!$B$30)^('30 Year IRR'!A9-1)-('30 Year IRR'!B9+'30 Year IRR'!C9+'30 Year IRR'!D9+12*(Numbers!$E$8+Numbers!$E$9)*(1+Numbers!$B$30)^('30 Year IRR'!A9-1)+12*(1-Numbers!$B$33)*Numbers!$B$16*(1+Numbers!$B$30)^('30 Year IRR'!A9-1)+12*Numbers!$B$33*Numbers!$B$19*(1+Numbers!$B$30)^('30 Year IRR'!A9-1)) -> 6146.1798 | F9: =Numbers!$B$35*('30 Year IRR'!E9+'30 Year IRR'!C9-IF(A9<27.5,Numbers!$E$14,0)) -> 1303.7461 | G9: =E9-F9 -> 4842.4338
A10: 7 | B10: =IF(A10<=Numbers!$B$5,Numbers!$E$4*(12*'30 Year IRR'!A10-1/(1+Numbers!$B$4/12)^(Numbers!$B$5*12-12*'30 Year IRR'!A10)*(1-1/(1+Numbers!$B$4/12)^(12*'30 Year IRR'!A10))/(Numbers!$B$4/12))-Numbers!$E$4*(12*'30 Year IRR'!A9-1/(1+Numbers!$B$4/12)^(Numbers!$B$5*12-12*'30 Year IRR'!A9)*(1-1/(1+Numbers!$B$4/12)^(12*'30 Year IRR'!A9))/(Numbers!$B$4/12)),0) -> 2453.7565 | C10: =IF(A10<=Numbers!$B$5,Numbers!$E$4*(1/(1+Numbers!$B$4/12))^(12*Numbers!$B$5-12*'30 Year IRR'!A10)*(1-1/(1+Numbers!$B$4/12)^(12*'30 Year IRR'!A10))/(Numbers!$B$4/12)-Numbers!$E$4*(1/(1+Numbers!$B$4/12))^(12*Numbers!$B$5-12*('30 Year IRR'!A10-1))*(1-1/(1+Numbers!$B$4/12)^(12*('30 Year IRR'!A10-1)))/(Numbers!$B$4/12),0) -> 1603.5368 | D10: =IF(SUM($C$3:C9)/Numbers!$E$3<Numbers!$B$10,12*Numbers!$E$7,0) -> 320.625 | E10: =12*Numbers!$B$15*(1-Numbers!$B$33)*(1+Numbers!$B$30)^('30 Year IRR'!A10-1)-('30 Year IRR'!B10+'30 Year IRR'!C10+'30 Year IRR'!D10+12*(Numbers!$E$8+Numbers!$E$9)*(1+Numbers!$B$30)^('30 Year IRR'!A10-1)+12*(1-Numbers!$B$33)*Numbers!$B$16*(1+Numbers!$B$30)^('30 Year IRR'!A10-1)+12*Numbers!$B$33*Numbers!$B$19*(1+Numbers!$B$30)^('30 Year IRR'!A10-1)) -> 6356.6618 | F10: =Numbers!$B$35*('30 Year IRR'!E10+'30 Year IRR'!C10-IF(A10<27.5,Numbers!$E$14,0)) -> 1371.8678 | G10: =E10-F10 -> 4984.794
A11: 8 | B11: =IF(A11<=Numbers!$B$5,Numbers!$E$4*(12*'30 Year IRR'!A11-1/(1+Numbers!$B$4/12)^(Numbers!$B$5*12-12*'30 Year IRR'!A11)*(1-1/(1+Numbers!$B$4/12)^(12*'30 Year IRR'!A11))/(Numbers!$B$4/12))-Numbers!$E$4*(12*'30 Year IRR'!A10-1/(1+Numbers!$B$4/12)^(Numbers!$B$5*12-12*'30 Year IRR'!A10)*(1-1/(1+Numbers!$B$4/12)^(12*'30 Year IRR'!A10))/(Numbers!$B$4/12)),0) -> 2389.2574 | C11: =IF(A11<=Numbers!$B$5,Numbers!$E$4*(1/(1+Numbers!$B$4/12))^(12*Numbers!$B$5-12*'30 Year IRR'!A11)*(1-1/(1+Numbers!$B$4/12)^(12*'30 Year IRR'!A11))/(Numbers!$B$4/12)-Numbers!$E$4*(1/(1+Numbers!$B$4/12))^(12*Numbers!$B$5-12*('30 Year IRR'!A11-1))*(1-1/(1+Numbers!$B$4/12)^(12*('30 Year IRR'!A11-1)))/(Numbers!$B$4/12),0) -> 1668.0359 | D11: =IF(SUM($C$3:C10)/Numbers!$E$3<Numbers!$B$10,12*Numbers!$E$7,0) -> 320.625 | E11: =12*Numbers!$B$15*(1-Numbers!$B$33)*(1+Numbers!$B$30)^('30 Year IRR'!A11-1)-('30 Year IRR'!B11+'30 Year IRR'!C11+'30 Year IRR'!D11+12*(Numbers!$E$8+Numbers!$E$9)*(1+Numbers!$B$30)^('30 Year IRR'!A11-1)+12*(1-Numbers!$B$33)*Numbers!$B$16*(1+Numbers!$B$30)^('30 Year IRR'!A11-1)+12*Numbers!$B$33*Numbers!$B$19*(1+Numbers!$B$30)^('30 Year IRR'!A11-1)) -> 6571.3534 | F11: =Numbers!$B$35*('30 Year IRR'!E11+'30 Year IRR'!C11-IF(A11<27.5,Numbers!$E$14,0)) -> 1441.6655 | G11: =E11-F11 -> 5129.6879
A12: 9 | B12: =IF(A12<=Numbers!$B$5,Numbers!$E$4*(12*'30 Year IRR'!A12-1/(1+Numbers!$B$4/12)^(Numbers!$B$5*12-12*'30 Year IRR'!A12)*(1-1/(1+Numbers!$B$4/12)^(12*'30 Year IRR'!A12))/(Numbers!$B$4/12))-Numbers!$E$4*(12*'30 Year IRR'!A11-1/(1+Numbers!$B$4/12)^(Numbers!$B$5*12-12*'30 Year IRR'!A11)*(1-1/(1+Numbers!$B$4/12)^(12*'30 Year IRR'!A11))/(Numbers!$B$4/12)),0) -> 2322.164 | C12: =IF(A12<=Numbers!$B$5,Numbers!$E$4*(1/(1+Numbers!$B$4/12))^(12*Numbers!$B$5-12*'30 Year IRR'!A12)*(1-1/(1+Numbers!$B$4/12)^(12*'30 Year IRR'!A12))/(Numbers!$B$4/12)-Numbers!$E$4*(1/(1+Numbers!$B$4/12))^(12*Numbers!$B$5-12*('30 Year IRR'!A12-1))*(1-1/(1+Numbers!$B$4/12)^(12*('30 Year IRR'!A12-1)))/(Numbers!$B$4/12),0) -> 1735.1294 | D12: =IF(SUM($C$3:C11)/Numbers!$E$3<Numbers!$B$10,12*Numbers!$E$7,0) -> 320.625 | E12: =12*Numbers!$B$15*(1-Numbers!$B$33)*(1+Numbers!$B$30)^('30 Year IRR'!A12-1)-('30 Year IRR'!B12+'30 Year IRR'!C12+'30 Year IRR'!D12+12*(Numbers!$E$8+Numbers!$E$9)*(1+Numbers!$B$30)^('30 Year IRR'!A12-1)+12*(1-Numbers!$B$33)*Numbers!$B$16*(1+Numbers!$B$30)^('30 Year IRR'!A12-1)+12*Numbers!$B$33*Numbers!$B$19*(1+Numbers!$B$30)^('30 Year IRR'!A12-1)) -> 6790.3389 | F12: =Numbers!$B$35*('30 Year IRR'!E12+'30 Year IRR'!C12-IF(A12<27.5,Numbers!$E$14,0)) -> 1513.1852 | G12: =E12-F12 -> 5277.1536
A13: 10 | B13: =IF(A13<=Numbers!$B$5,Numbers!$E$4*(12*'30 Year IRR'!A13-1/(1+Numbers!$B$4/12)^(Numbers!$B$5*12-12*'30 Year IRR'!A13)*(1-1/(1+Numbers!$B$4/12)^(12*'30 Year IRR'!A13))/(Numbers!$B$4/12))-Numbers!$E$4*(12*'30 Year IRR'!A12-1/(1+Numbers!$B$4/12)^(Numbers!$B$5*12-12*'30 Year IRR'!A12)*(1-1/(1+Numbers!$B$4/12)^(12*'30 Year IRR'!A12))/(Numbers!$B$4/12)),0) -> 2252.3719 | C13: =IF(A13<=Numbers!$B$5,Numbers!$E$4*(1/(1+Numbers!$B$4/12))^(12*Numbers!$B$5-12*'30 Year IRR'!A13)*(1-1/(1+Numbers!$B$4/12)^(12*'30 Year IRR'!A13))/(Numbers!$B$4/12)-Numbers!$E$4*(1/(1+Numbers!$B$4/12))^(12*Numbers!$B$5-12*('30 Year IRR'!A13-1))*(1-1/(1+Numbers!$B$4/12)^(12*('30 Year IRR'!A13-1)))/(Numbers!$B$4/12),0) -> 1804.9215 | D13: =IF(SUM($C$3:C12)/Numbers!$E$3<Numbers!$B$10,12*Numbers!$E$7,0) -> 320.625 | E13: =12*Numbers!$B$15*(1-Numbers!$B$33)*(1+Numbers!$B$30)^('30 Year IRR'!A13-1)-('30 Year IRR'!B13+'30 Year IRR'!C13+'30 Year IRR'!D13+12*(Numbers!$E$8+Numbers!$E$9)*(1+Numbers!$B$30)^('30 Year IRR'!A13-1)+12*(1-Numbers!$B$33)*Numbers!$B$16*(1+Numbers!$B$30)^('30 Year IRR'!A13-1)+12*Numbers!$B$33*Numbers!$B$19*(1+Numbers!$B$30)^('30 Year IRR'!A13-1)) -> 7013.704 | F13: =Numbers!$B$35*('30 Year IRR'!E13+'30 Year IRR'!C13-IF(A13<27.5,Numbers!$E$14,0)) -> 1586.4746 | G13: =E13-F13 -> 5427.2294
A14: 11 | B14: =IF(A14<=Numbers!$B$5,Numbers!$E$4*(12*'30 Year IRR'!A14-1/(1+Numbers!$B$4/12)^(Numbers!$B$5*12-12*'30 Year IRR'!A14)*(1-1/(1+Numbers!$B$4/12)^(12*'30 Year IRR'!A14))/(Numbers!$B$4/12))-Numbers!$E$4*(12*'30 Year IRR'!A13-1/(1+Numbers!$B$4/12)^(Numbers!$B$5*12-12*'30 Year IRR'!A13)*(1-1/(1+Numbers!$B$4/12)^(12*'30 Year IRR'!A13))/(Numbers!$B$4/12)),0) -> 2179.7725 | C14: =IF(A14<=Numbers!$B$5,Numbers!$E$4*(1/(1+Numbers!$B$4/12))^(12*Numbers!$B$5-12*'30 Year IRR'!A14)*(1-1/(1+Numbers!$B$4/12)^(12*'30 Year IRR'!A14))/(Numbers!$B$4/12)-Numbers!$E$4*(1/(1+Numbers!$B$4/12))^(12*Numbers!$B$5-12*('30 Year IRR'!A14-1))*(1-1/(1+Numbers!$B$4/12)^(12*('30 Year IRR'!A14-1)))/(Numbers!$B$4/12),0) -> 1877.5209 | D14: =IF(SUM($C$3:C13)/Numbers!$E$3<Numbers!$B$10,12*Numbers!$E$7,0) -> 0 | E14: =12*Numbers!$B$15*(1-Numbers!$B$33)*(1+Numbers!$B$30)^('30 Year IRR'!A14-1)-('30 Year IRR'!B14+'30 Year IRR'!C14+'30 Year IRR'!D14+12*(Numbers!$E$8+Numbers!$E$9)*(1+Numbers!$B$30)^('30 Year IRR'!A14-1)+12*(1-Numbers!$B$33)*Numbers!$B$16*(1+Numbers!$B$30)^('30 Year IRR'!A14-1)+12*Numbers!$B$33*Numbers!$B$19*(1+Numbers!$B$30)^('30 Year IRR'!A14-1)) -> 7562.1614 | F14: =Numbers!$B$35*('30 Year IRR'!E14+'30 Year IRR'!C14-IF(A14<27.5,Numbers!$E$14,0)) -> 1741.7388 | G14: =E14-F14 -> 5820.4227
A15: 12 | B15: =IF(A15<=Numbers!$B$5,Numbers!$E$4*(12*'30 Year IRR'!A15-1/(1+Numbers!$B$4/12)^(Numbers!$B$5*12-12*'30 Year IRR'!A15)*(1-1/(1+Numbers!$B$4/12)^(12*'30 Year IRR'!A15))/(Numbers!$B$4/12))-Numbers!$E$4*(12*'30 Year IRR'!A14-1/(1+Numbers!$B$4/12)^(Numbers!$B$5*12-12*'30 Year IRR'!A14)*(1-1/(1+Numbers!$B$4/12)^(12*'30 Year IRR'!A14))/(Numbers!$B$4/12)),0) -> 2104.2529 | C15: =IF(A15<=Numbers!$B$5,Numbers!$E$4*(1/(1+Numbers!$B$4/12))^(12*Numbers!$B$5-12*'30 Year IRR'!A15)*(1-1/(1+Numbers!$B$4/12)^(12*'30 Year IRR'!A15))/(Numbers!$B$4/12)-Numbers!$E$4*(1/(1+Numbers!$B$4/12))^(12*Numbers!$B$5-12*('30 Year IRR'!A15-1))*(1-1/(1+Numbers!$B$4/12)^(12*('30 Year IRR'!A15-1)))/(Numbers!$B$4/12),0) -> 1953.0405 | D15: =IF(SUM($C$3:C14)/Numbers!$E$3<Numbers!$B$10,12*Numbers!$E$7,0) -> 0 | E15: =12*Numbers!$B$15*(1-Numbers!$B$33)*(1+Numbers!$B$30)^('30 Year IRR'!A15-1)-('30 Year IRR'!B15+'30 Year IRR'!C15+'30 Year IRR'!D15+12*(Numbers!$E$8+Numbers!$E$9)*(1+Numbers!$B$30)^('30 Year IRR'!A15-1)+12*(1-Numbers!$B$33)*Numbers!$B$16*(1+Numbers!$B$30)^('30 Year IRR'!A15-1)+12*Numbers!$B$33*Numbers!$B$19*(1+Numbers!$B$30)^('30 Year IRR'!A15-1)) -> 7794.5505 | F15: =Numbers!$B$35*('30 Year IRR'!E15+'30 Year IRR'!C15-IF(A15<27.5,Numbers!$E$14,0)) -> 1818.7159 | G15: =E15-F15 -> 5975.8346
A16: 13 | B16: =IF(A16<=Numbers!$B$5,Numbers!$E$4*(12*'30 Year IRR'!A16-1/(1+Numbers!$B$4/12)^(Numbers!$B$5*12-12*'30 Year IRR'!A16)*(1-1/(1+Numbers!$B$4/12)^(12*'30 Year IRR'!A16))/(Numbers!$B$4/12))-Numbers!$E$4*(12*'30 Year IRR'!A15-1/(1+Numbers!$B$4/12)^(Numbers!$B$5*12-12*'30 Year IRR'!A15)*(1-1/(1+Numbers!$B$4/12)^(12*'30 Year IRR'!A15))/(Numbers!$B$4/12)),0) -> 2025.6957 | C16: =IF(A16<=Numbers!$B$5,Numbers!$E$4*(1/(1+Numbers!$B$4/12))^(12*Numbers!$B$5-12*'30 Year IRR'!A16)*(1-1/(1+Numbers!$B$4/12)^(12*'30 Year IRR'!A16))/(Numbers!$B$4/12)-Numbers!$E$4*(1/(1+Numbers!$B$4/12))^(12*Numbers!$B$5-12*('30 Year IRR'!A16-1))*(1-1/(1+Numbers!$B$4/12)^(12*('30 Year IRR'!A16-1)))/(Numbers!$B$4/12),0) -> 2031.5976 | D16: =IF(SUM($C$3:C15)/Numbers!$E$3<Numbers!$B$10,12*Numbers!$E$7,0) -> 0 | E16: =12*Numbers!$B$15*(1-Numbers!$B$33)*(1+Numbers!$B$30)^('30 Year IRR'!A16-1)-('30 Year IRR'!B16+'30 Year IRR'!C16+'30 Year IRR'!D16+12*(Numbers!$E$8+Numbers!$E$9)*(1+Numbers!$B$30)^('30 Year IRR'!A16-1)+12*(1-Numbers!$B$33)*Numbers!$B$16*(1+Numbers!$B$30)^('30 Year IRR'!A16-1)+12*Numbers!$B$33*Numbers!$B$19*(1+Numbers!$B$30)^('30 Year IRR'!A16-1)) -> 8031.5874 | F16: =Numbers!$B$35*('30 Year IRR'!E16+'30 Year IRR'!C16-IF(A16<27.5,Numbers!$E$14,0)) -> 1897.6144 | G16: =E16-F16 -> 6133.973
... A32: 29 | B32: =IF(A32<=Numbers!$B$5,Numbers!$E$4*(12*'30 Year IRR'!A32-1/(1+Numbers!$B$4/12)^(Numbers!$B$5*12-12*'30 Year IRR'!A32)*(1-1/(1+Numbers!$B$4/12)^(12*'30 Year IRR'!A32))/(Numbers!$B$4/12))-Numbers!$E$4*(12*'30 Year IRR'!A31-1/(1+Numbers!$B$4/12)^(Numbers!$B$5*12-12*'30 Year IRR'!A31)*(1-1/(1+Numbers!$B$4/12)^(12*'30 Year IRR'!A31))/(Numbers!$B$4/12)),0) -> 239.07235 | C32: =IF(A32<=Numbers!$B$5,Numbers!$E$4*(1/(1+Numbers!$B$4/12))^(12*Numbers!$B$5-12*'30 Year IRR'!A32)*(1-1/(1+Numbers!$B$4/12)^(12*'30 Year IRR'!A32))/(Numbers!$B$4/12)-Numbers!$E$4*(1/(1+Numbers!$B$4/12))^(12*Numbers!$B$5-12*('30 Year IRR'!A32-1))*(1-1/(1+Numbers!$B$4/12)^(12*('30 Year IRR'!A32-1)))/(Numbers!$B$4/12),0) -> 3818.221 | D32: =IF(SUM($C$3:C31)/Numbers!$E$3<Numbers!$B$10,12*Numbers!$E$7,0) -> 0 | E32: =12*Numbers!$B$15*(1-Numbers!$B$33)*(1+Numbers!$B$30)^('30 Year IRR'!A32-1)-('30 Year IRR'!B32+'30 Year IRR'!C32+'30 Year IRR'!D32+12*(Numbers!$E$8+Numbers!$E$9)*(1+Numbers!$B$30)^('30 Year IRR'!A32-1)+12*(1-Numbers!$B$33)*Numbers!$B$16*(1+Numbers!$B$30)^('30 Year IRR'!A32-1)+12*Numbers!$B$33*Numbers!$B$19*(1+Numbers!$B$30)^('30 Year IRR'!A32-1)) -> 12538.149 | F32: =Numbers!$B$35*('30 Year IRR'!E32+'30 Year IRR'!C32-IF(A32<27.5,Numbers!$E$14,0)) -> 4089.0926 | G32: =E32-F32 -> 8449.0568
A33: 30 | B33: =IF(A33<=Numbers!$B$5,Numbers!$E$4*(12*'30 Year IRR'!A33-1/(1+Numbers!$B$4/12)^(Numbers!$B$5*12-12*'30 Year IRR'!A33)*(1-1/(1+Numbers!$B$4/12)^(12*'30 Year IRR'!A33))/(Numbers!$B$4/12))-Numbers!$E$4*(12*'30 Year IRR'!A32-1/(1+Numbers!$B$4/12)^(Numbers!$B$5*12-12*'30 Year IRR'!A32)*(1-1/(1+Numbers!$B$4/12)^(12*'30 Year IRR'!A32))/(Numbers!$B$4/12)),0) -> 85.491976 | C33: =IF(A33<=Numbers!$B$5,Numbers!$E$4*(1/(1+Numbers!$B$4/12))^(12*Numbers!$B$5-12*'30 Year IRR'!A33)*(1-1/(1+Numbers!$B$4/12)^(12*'30 Year IRR'!A33))/(Numbers!$B$4/12)-Numbers!$E$4*(1/(1+Numbers!$B$4/12))^(12*Numbers!$B$5-12*('30 Year IRR'!A33-1))*(1-1/(1+Numbers!$B$4/12)^(12*('30 Year IRR'!A33-1)))/(Numbers!$B$4/12),0) -> 3971.8014 | D33: =IF(SUM($C$3:C32)/Numbers!$E$3<Numbers!$B$10,12*Numbers!$E$7,0) -> 0 | E33: =12*Numbers!$B$15*(1-Numbers!$B$33)*(1+Numbers!$B$30)^('30 Year IRR'!A33-1)-('30 Year IRR'!B33+'30 Year IRR'!C33+'30 Year IRR'!D33+12*(Numbers!$E$8+Numbers!$E$9)*(1+Numbers!$B$30)^('30 Year IRR'!A33-1)+12*(1-Numbers!$B$33)*Numbers!$B$16*(1+Numbers!$B$30)^('30 Year IRR'!A33-1)+12*Numbers!$B$33*Numbers!$B$19*(1+Numbers!$B$30)^('30 Year IRR'!A33-1)) -> 12870.058 | F33: =Numbers!$B$35*('30 Year IRR'!E33+'30 Year IRR'!C33-IF(A33<27.5,Numbers!$E$14,0)) -> 4210.4649 | G33: =E33-F33+D42 -> 156710.21
C36: Sale Price: | D36: =(1+Numbers!$B$31)^30*(Numbers!B3+Numbers!B8) -> 194181 | F36: Lifetime Cash: | G36: =SUM(G4:G33)-D42 -> 193405.82
C37: Adj Sale Price: | D37: =(1-Numbers!B23)*'30 Year IRR'!D36-Numbers!B24 -> 179530.14
C38: Depreciated Basis: | D38: =Numbers!E13-27.5*Numbers!E14 -> 15000
C39: Capital Gains: | D39: =(D37-Numbers!E13)*Numbers!B25 -> 14479.521
C40: Depr Recapture: | D40: =Numbers!B26*(Numbers!E13-'30 Year IRR'!D38) -> 17000
C41: Principal Owed: | D41: =Numbers!E3-SUM(C4:C33) -> 0
C42: Sale Profit: | D42: =D37-D39-D40-D41 -> 148050.62
C44: LIFETIME IRR: | D44: =IRR(G3:G33) -> 0.3498101

Sheet 20 Year IRR
A1: Year | B1: Interest Paid | C1: Principal Paid | D1: PMI Paid | E1: Gross Income | F1: Income Taxes | G1: Net Cash Flow
A3: 0 | G3: =-Numbers!E23 -> -11750
A4: 1 | B4: =IF(A4<=Numbers!$B$5,Numbers!$E$4*(12*'30 Year IRR'!A4-1/(1+Numbers!$B$4/12)^(Numbers!$B$5*12-12*'30 Year IRR'!A4)*(1-1/(1+Numbers!$B$4/12)^(12*'30 Year IRR'!A4))/(Numbers!$B$4/12))-Numbers!$E$4*(12*'30 Year IRR'!A3-1/(1+Numbers!$B$4/12)^(Numbers!$B$5*12-12*'30 Year IRR'!A3)*(1-1/(1+Numbers!$B$4/12)^(12*'30 Year IRR'!A3))/(Numbers!$B$4/12)),0) -> 2791.6243 | C4: =IF(A4<=Numbers!$B$5,Numbers!$E$4*(1/(1+Numbers!$B$4/12))^(12*Numbers!$B$5-12*'30 Year IRR'!A4)*(1-1/(1+Numbers!$B$4/12)^(12*'30 Year IRR'!A4))/(Numbers!$B$4/12)-Numbers!$E$4*(1/(1+Numbers!$B$4/12))^(12*Numbers!$B$5-12*('30 Year IRR'!A4-1))*(1-1/(1+Numbers!$B$4/12)^(12*('30 Year IRR'!A4-1)))/(Numbers!$B$4/12),0) -> 1265.6691 | D4: =IF(SUM($C$3:C3)/Numbers!$E$3<Numbers!$B$10,12*Numbers!$E$7,0) -> 320.625 | E4: =12*Numbers!$B$15*(1-Numbers!$B$33)*(1+Numbers!$B$30)^('30 Year IRR'!A4-1)-('30 Year IRR'!B4+'30 Year IRR'!C4+'30 Year IRR'!D4+12*(Numbers!$E$8+Numbers!$E$9)*(1+Numbers!$B$30)^('30 Year IRR'!A4-1)+12*(1-Numbers!$B$33)*Numbers!$B$16*(1+Numbers!$B$30)^('30 Year IRR'!A4-1)+12*Numbers!$B$33*Numbers!$B$19*(1+Numbers!$B$30)^('30 Year IRR'!A4-1))-Numbers!B11*Numbers!B15 -> 2754.0816 | F4: =Numbers!$B$35*('30 Year IRR'!E4+'30 Year IRR'!C4-IF(A4<27.5,Numbers!$E$14,0)) -> 386.75587 | G4: =E4-F4 -> 2367.3258
A5: 2 | B5: =IF(A5<=Numbers!$B$5,Numbers!$E$4*(12*'30 Year IRR'!A5-1/(1+Numbers!$B$4/12)^(Numbers!$B$5*12-12*'30 Year IRR'!A5)*(1-1/(1+Numbers!$B$4/12)^(12*'30 Year IRR'!A5))/(Numbers!$B$4/12))-Numbers!$E$4*(12*'30 Year IRR'!A4-1/(1+Numbers!$B$4/12)^(Numbers!$B$5*12-12*'30 Year IRR'!A4)*(1-1/(1+Numbers!$B$4/12)^(12*'30 Year IRR'!A4))/(Numbers!$B$4/12)),0) -> 2740.7152 | C5: =IF(A5<=Numbers!$B$5,Numbers!$E$4*(1/(1+Numbers!$B$4/12))^(12*Numbers!$B$5-12*'30 Year IRR'!A5)*(1-1/(1+Numbers!$B$4/12)^(12*'30 Year IRR'!A5))/(Numbers!$B$4/12)-Numbers!$E$4*(1/(1+Numbers!$B$4/12))^(12*Numbers!$B$5-12*('30 Year IRR'!A5-1))*(1-1/(1+Numbers!$B$4/12)^(12*('30 Year IRR'!A5-1)))/(Numbers!$B$4/12),0) -> 1316.5781 | D5: =IF(SUM($C$3:C4)/Numbers!$E$3<Numbers!$B$10,12*Numbers!$E$7,0) -> 320.625 | E5: =12*Numbers!$B$15*(1-Numbers!$B$33)*(1+Numbers!$B$30)^('30 Year IRR'!A5-1)-('30 Year IRR'!B5+'30 Year IRR'!C5+'30 Year IRR'!D5+12*(Numbers!$E$8+Numbers!$E$9)*(1+Numbers!$B$30)^('30 Year IRR'!A5-1)+12*(1-Numbers!$B$33)*Numbers!$B$16*(1+Numbers!$B$30)^('30 Year IRR'!A5-1)+12*Numbers!$B$33*Numbers!$B$19*(1+Numbers!$B$30)^('30 Year IRR'!A5-1)) -> 5344.7216 | F5: =Numbers!$B$35*('30 Year IRR'!E5+'30 Year IRR'!C5-IF(A5<27.5,Numbers!$E$14,0)) -> 1047.1431 | G5: =E5-F5 -> 4297.5785
A6: 3 | B6: =IF(A6<=Numbers!$B$5,Numbers!$E$4*(12*'30 Year IRR'!A6-1/(1+Numbers!$B$4/12)^(Numbers!$B$5*12-12*'30 Year IRR'!A6)*(1-1/(1+Numbers!$B$4/12)^(12*'30 Year IRR'!A6))/(Numbers!$B$4/12))-Numbers!$E$4*(12*'30 Year IRR'!A5-1/(1+Numbers!$B$4/12)^(Numbers!$B$5*12-12*'30 Year IRR'!A5)*(1-1/(1+Numbers!$B$4/12)^(12*'30 Year IRR'!A5))/(Numbers!$B$4/12)),0) -> 2687.7585 | C6: =IF(A6<=Numbers!$B$5,Numbers!$E$4*(1/(1+Numbers!$B$4/12))^(12*Numbers!$B$5-12*'30 Year IRR'!A6)*(1-1/(1+Numbers!$B$4/12)^(12*'30 Year IRR'!A6))/(Numbers!$B$4/12)-Numbers!$E$4*(1/(1+Numbers!$B$4/12))^(12*Numbers!$B$5-12*('30 Year IRR'!A6-1))*(1-1/(1+Numbers!$B$4/12)^(12*('30 Year IRR'!A6-1)))/(Numbers!$B$4/12),0) -> 1369.5349 | D6: =IF(SUM($C$3:C5)/Numbers!$E$3<Numbers!$B$10,12*Numbers!$E$7,0) -> 320.625 | E6: =12*Numbers!$B$15*(1-Numbers!$B$33)*(1+Numbers!$B$30)^('30 Year IRR'!A6-1)-('30 Year IRR'!B6+'30 Year IRR'!C6+'30 Year IRR'!D6+12*(Numbers!$E$8+Numbers!$E$9)*(1+Numbers!$B$30)^('30 Year IRR'!A6-1)+12*(1-Numbers!$B$33)*Numbers!$B$16*(1+Numbers!$B$30)^('30 Year IRR'!A6-1)+12*Numbers!$B$33*Numbers!$B$19*(1+Numbers!$B$30)^('30 Year IRR'!A6-1)) -> 5539.1744 | F6: =Numbers!$B$35*('30 Year IRR'!E6+'30 Year IRR'!C6-IF(A6<27.5,Numbers!$E$14,0)) -> 1108.9955 | G6: =E6-F6 -> 4430.1789
A7: 4 | B7: =IF(A7<=Numbers!$B$5,Numbers!$E$4*(12*'30 Year IRR'!A7-1/(1+Numbers!$B$4/12)^(Numbers!$B$5*12-12*'30 Year IRR'!A7)*(1-1/(1+Numbers!$B$4/12)^(12*'30 Year IRR'!A7))/(Numbers!$B$4/12))-Numbers!$E$4*(12*'30 Year IRR'!A6-1/(1+Numbers!$B$4/12)^(Numbers!$B$5*12-12*'30 Year IRR'!A6)*(1-1/(1+Numbers!$B$4/12)^(12*'30 Year IRR'!A6))/(Numbers!$B$4/12)),0) -> 2632.6717 | C7: =IF(A7<=Numbers!$B$5,Numbers!$E$4*(1/(1+Numbers!$B$4/12))^(12*Numbers!$B$5-12*'30 Year IRR'!A7)*(1-1/(1+Numbers!$B$4/12)^(12*'30 Year IRR'!A7))/(Numbers!$B$4/12)-Numbers!$E$4*(1/(1+Numbers!$B$4/12))^(12*Numbers!$B$5-12*('30 Year IRR'!A7-1))*(1-1/(1+Numbers!$B$4/12)^(12*('30 Year IRR'!A7-1)))/(Numbers!$B$4/12),0) -> 1424.6217 | D7: =IF(SUM($C$3:C6)/Numbers!$E$3<Numbers!$B$10,12*Numbers!$E$7,0) -> 320.625 | E7: =12*Numbers!$B$15*(1-Numbers!$B$33)*(1+Numbers!$B$30)^('30 Year IRR'!A7-1)-('30 Year IRR'!B7+'30 Year IRR'!C7+'30 Year IRR'!D7+12*(Numbers!$E$8+Numbers!$E$9)*(1+Numbers!$B$30)^('30 Year IRR'!A7-1)+12*(1-Numbers!$B$33)*Numbers!$B$16*(1+Numbers!$B$30)^('30 Year IRR'!A7-1)+12*Numbers!$B$33*Numbers!$B$19*(1+Numbers!$B$30)^('30 Year IRR'!A7-1)) -> 5737.5163 | F7: =Numbers!$B$35*('30 Year IRR'!E7+'30 Year IRR'!C7-IF(A7<27.5,Numbers!$E$14,0)) -> 1172.3527 | G7: =E7-F7 -> 4565.1636
A8: 5 | B8: =IF(A8<=Numbers!$B$5,Numbers!$E$4*(12*'30 Year IRR'!A8-1/(1+Numbers!$B$4/12)^(Numbers!$B$5*12-12*'30 Year IRR'!A8)*(1-1/(1+Numbers!$B$4/12)^(12*'30 Year IRR'!A8))/(Numbers!$B$4/12))-Numbers!$E$4*(12*'30 Year IRR'!A7-1/(1+Numbers!$B$4/12)^(Numbers!$B$5*12-12*'30 Year IRR'!A7)*(1-1/(1+Numbers!$B$4/12)^(12*'30 Year IRR'!A7))/(Numbers!$B$4/12)),0) -> 2575.3691 | C8: =IF(A8<=Numbers!$B$5,Numbers!$E$4*(1/(1+Numbers!$B$4/12))^(12*Numbers!$B$5-12*'30 Year IRR'!A8)*(1-1/(1+Numbers!$B$4/12)^(12*'30 Year IRR'!A8))/(Numbers!$B$4/12)-Numbers!$E$4*(1/(1+Numbers!$B$4/12))^(12*Numbers!$B$5-12*('30 Year IRR'!A8-1))*(1-1/(1+Numbers!$B$4/12)^(12*('30 Year IRR'!A8-1)))/(Numbers!$B$4/12),0) -> 1481.9243 | D8: =IF(SUM($C$3:C7)/Numbers!$E$3<Numbers!$B$10,12*Numbers!$E$7,0) -> 320.625 | E8: =12*Numbers!$B$15*(1-Numbers!$B$33)*(1+Numbers!$B$30)^('30 Year IRR'!A8-1)-('30 Year IRR'!B8+'30 Year IRR'!C8+'30 Year IRR'!D8+12*(Numbers!$E$8+Numbers!$E$9)*(1+Numbers!$B$30)^('30 Year IRR'!A8-1)+12*(1-Numbers!$B$33)*Numbers!$B$16*(1+Numbers!$B$30)^('30 Year IRR'!A8-1)+12*Numbers!$B$33*Numbers!$B$19*(1+Numbers!$B$30)^('30 Year IRR'!A8-1)) -> 5939.825 | F8: =Numbers!$B$35*('30 Year IRR'!E8+'30 Year IRR'!C8-IF(A8<27.5,Numbers!$E$14,0)) -> 1237.2555 | G8: =E8-F8 -> 4702.5695
A9: 6 | B9: =IF(A9<=Numbers!$B$5,Numbers!$E$4*(12*'30 Year IRR'!A9-1/(1+Numbers!$B$4/12)^(Numbers!$B$5*12-12*'30 Year IRR'!A9)*(1-1/(1+Numbers!$B$4/12)^(12*'30 Year IRR'!A9))/(Numbers!$B$4/12))-Numbers!$E$4*(12*'30 Year IRR'!A8-1/(1+Numbers!$B$4/12)^(Numbers!$B$5*12-12*'30 Year IRR'!A8)*(1-1/(1+Numbers!$B$4/12)^(12*'30 Year IRR'!A8))/(Numbers!$B$4/12)),0) -> 2515.7616 | C9: =IF(A9<=Numbers!$B$5,Numbers!$E$4*(1/(1+Numbers!$B$4/12))^(12*Numbers!$B$5-12*'30 Year IRR'!A9)*(1-1/(1+Numbers!$B$4/12)^(12*'30 Year IRR'!A9))/(Numbers!$B$4/12)-Numbers!$E$4*(1/(1+Numbers!$B$4/12))^(12*Numbers!$B$5-12*('30 Year IRR'!A9-1))*(1-1/(1+Numbers!$B$4/12)^(12*('30 Year IRR'!A9-1)))/(Numbers!$B$4/12),0) -> 1541.5318 | D9: =IF(SUM($C$3:C8)/Numbers!$E$3<Numbers!$B$10,12*Numbers!$E$7,0) -> 320.625 | E9: =12*Numbers!$B$15*(1-Numbers!$B$33)*(1+Numbers!$B$30)^('30 Year IRR'!A9-1)-('30 Year IRR'!B9+'30 Year IRR'!C9+'30 Year IRR'!D9+12*(Numbers!$E$8+Numbers!$E$9)*(1+Numbers!$B$30)^('30 Year IRR'!A9-1)+12*(1-Numbers!$B$33)*Numbers!$B$16*(1+Numbers!$B$30)^('30 Year IRR'!A9-1)+12*Numbers!$B$33*Numbers!$B$19*(1+Numbers!$B$30)^('30 Year IRR'!A9-1)) -> 6146.1798 | F9: =Numbers!$B$35*('30 Year IRR'!E9+'30 Year IRR'!C9-IF(A9<27.5,Numbers!$E$14,0)) -> 1303.7461 | G9: =E9-F9 -> 4842.4338
A10: 7 | B10: =IF(A10<=Numbers!$B$5,Numbers!$E$4*(12*'30 Year IRR'!A10-1/(1+Numbers!$B$4/12)^(Numbers!$B$5*12-12*'30 Year IRR'!A10)*(1-1/(1+Numbers!$B$4/12)^(12*'30 Year IRR'!A10))/(Numbers!$B$4/12))-Numbers!$E$4*(12*'30 Year IRR'!A9-1/(1+Numbers!$B$4/12)^(Numbers!$B$5*12-12*'30 Year IRR'!A9)*(1-1/(1+Numbers!$B$4/12)^(12*'30 Year IRR'!A9))/(Numbers!$B$4/12)),0) -> 2453.7565 | C10: =IF(A10<=Numbers!$B$5,Numbers!$E$4*(1/(1+Numbers!$B$4/12))^(12*Numbers!$B$5-12*'30 Year IRR'!A10)*(1-1/(1+Numbers!$B$4/12)^(12*'30 Year IRR'!A10))/(Numbers!$B$4/12)-Numbers!$E$4*(1/(1+Numbers!$B$4/12))^(12*Numbers!$B$5-12*('30 Year IRR'!A10-1))*(1-1/(1+Numbers!$B$4/12)^(12*('30 Year IRR'!A10-1)))/(Numbers!$B$4/12),0) -> 1603.5368 | D10: =IF(SUM($C$3:C9)/Numbers!$E$3<Numbers!$B$10,12*Numbers!$E$7,0) -> 320.625 | E10: =12*Numbers!$B$15*(1-Numbers!$B$33)*(1+Numbers!$B$30)^('30 Year IRR'!A10-1)-('30 Year IRR'!B10+'30 Year IRR'!C10+'30 Year IRR'!D10+12*(Numbers!$E$8+Numbers!$E$9)*(1+Numbers!$B$30)^('30 Year IRR'!A10-1)+12*(1-Numbers!$B$33)*Numbers!$B$16*(1+Numbers!$B$30)^('30 Year IRR'!A10-1)+12*Numbers!$B$33*Numbers!$B$19*(1+Numbers!$B$30)^('30 Year IRR'!A10-1)) -> 6356.6618 | F10: =Numbers!$B$35*('30 Year IRR'!E10+'30 Year IRR'!C10-IF(A10<27.5,Numbers!$E$14,0)) -> 1371.8678 | G10: =E10-F10 -> 4984.794
A11: 8 | B11: =IF(A11<=Numbers!$B$5,Numbers!$E$4*(12*'30 Year IRR'!A11-1/(1+Numbers!$B$4/12)^(Numbers!$B$5*12-12*'30 Year IRR'!A11)*(1-1/(1+Numbers!$B$4/12)^(12*'30 Year IRR'!A11))/(Numbers!$B$4/12))-Numbers!$E$4*(12*'30 Year IRR'!A10-1/(1+Numbers!$B$4/12)^(Numbers!$B$5*12-12*'30 Year IRR'!A10)*(1-1/(1+Numbers!$B$4/12)^(12*'30 Year IRR'!A10))/(Numbers!$B$4/12)),0) -> 2389.2574 | C11: =IF(A11<=Numbers!$B$5,Numbers!$E$4*(1/(1+Numbers!$B$4/12))^(12*Numbers!$B$5-12*'30 Year IRR'!A11)*(1-1/(1+Numbers!$B$4/12)^(12*'30 Year IRR'!A11))/(Numbers!$B$4/12)-Numbers!$E$4*(1/(1+Numbers!$B$4/12))^(12*Numbers!$B$5-12*('30 Year IRR'!A11-1))*(1-1/(1+Numbers!$B$4/12)^(12*('30 Year IRR'!A11-1)))/(Numbers!$B$4/12),0) -> 1668.0359 | D11: =IF(SUM($C$3:C10)/Numbers!$E$3<Numbers!$B$10,12*Numbers!$E$7,0) -> 320.625 | E11: =12*Numbers!$B$15*(1-Numbers!$B$33)*(1+Numbers!$B$30)^('30 Year IRR'!A11-1)-('30 Year IRR'!B11+'30 Year IRR'!C11+'30 Year IRR'!D11+12*(Numbers!$E$8+Numbers!$E$9)*(1+Numbers!$B$30)^('30 Year IRR'!A11-1)+12*(1-Numbers!$B$33)*Numbers!$B$16*(1+Numbers!$B$30)^('30 Year IRR'!A11-1)+12*Numbers!$B$33*Numbers!$B$19*(1+Numbers!$B$30)^('30 Year IRR'!A11-1)) -> 6571.3534 | F11: =Numbers!$B$35*('30 Year IRR'!E11+'30 Year IRR'!C11-IF(A11<27.5,Numbers!$E$14,0)) -> 1441.6655 | G11: =E11-F11 -> 5129.6879
A12: 9 | B12: =IF(A12<=Numbers!$B$5,Numbers!$E$4*(12*'30 Year IRR'!A12-1/(1+Numbers!$B$4/12)^(Numbers!$B$5*12-12*'30 Year IRR'!A12)*(1-1/(1+Numbers!$B$4/12)^(12*'30 Year IRR'!A12))/(Numbers!$B$4/12))-Numbers!$E$4*(12*'30 Year IRR'!A11-1/(1+Numbers!$B$4/12)^(Numbers!$B$5*12-12*'30 Year IRR'!A11)*(1-1/(1+Numbers!$B$4/12)^(12*'30 Year IRR'!A11))/(Numbers!$B$4/12)),0) -> 2322.164 | C12: =IF(A12<=Numbers!$B$5,Numbers!$E$4*(1/(1+Numbers!$B$4/12))^(12*Numbers!$B$5-12*'30 Year IRR'!A12)*(1-1/(1+Numbers!$B$4/12)^(12*'30 Year IRR'!A12))/(Numbers!$B$4/12)-Numbers!$E$4*(1/(1+Numbers!$B$4/12))^(12*Numbers!$B$5-12*('30 Year IRR'!A12-1))*(1-1/(1+Numbers!$B$4/12)^(12*('30 Year IRR'!A12-1)))/(Numbers!$B$4/12),0) -> 1735.1294 | D12: =IF(SUM($C$3:C11)/Numbers!$E$3<Numbers!$B$10,12*Numbers!$E$7,0) -> 320.625 | E12: =12*Numbers!$B$15*(1-Numbers!$B$33)*(1+Numbers!$B$30)^('30 Year IRR'!A12-1)-('30 Year IRR'!B12+'30 Year IRR'!C12+'30 Year IRR'!D12+12*(Numbers!$E$8+Numbers!$E$9)*(1+Numbers!$B$30)^('30 Year IRR'!A12-1)+12*(1-Numbers!$B$33)*Numbers!$B$16*(1+Numbers!$B$30)^('30 Year IRR'!A12-1)+12*Numbers!$B$33*Numbers!$B$19*(1+Numbers!$B$30)^('30 Year IRR'!A12-1)) -> 6790.3389 | F12: =Numbers!$B$35*('30 Year IRR'!E12+'30 Year IRR'!C12-IF(A12<27.5,Numbers!$E$14,0)) -> 1513.1852 | G12: =E12-F12 -> 5277.1536
A13: 10 | B13: =IF(A13<=Numbers!$B$5,Numbers!$E$4*(12*'30 Year IRR'!A13-1/(1+Numbers!$B$4/12)^(Numbers!$B$5*12-12*'30 Year IRR'!A13)*(1-1/(1+Numbers!$B$4/12)^(12*'30 Year IRR'!A13))/(Numbers!$B$4/12))-Numbers!$E$4*(12*'30 Year IRR'!A12-1/(1+Numbers!$B$4/12)^(Numbers!$B$5*12-12*'30 Year IRR'!A12)*(1-1/(1+Numbers!$B$4/12)^(12*'30 Year IRR'!A12))/(Numbers!$B$4/12)),0) -> 2252.3719 | C13: =IF(A13<=Numbers!$B$5,Numbers!$E$4*(1/(1+Numbers!$B$4/12))^(12*Numbers!$B$5-12*'30 Year IRR'!A13)*(1-1/(1+Numbers!$B$4/12)^(12*'30 Year IRR'!A13))/(Numbers!$B$4/12)-Numbers!$E$4*(1/(1+Numbers!$B$4/12))^(12*Numbers!$B$5-12*('30 Year IRR'!A13-1))*(1-1/(1+Numbers!$B$4/12)^(12*('30 Year IRR'!A13-1)))/(Numbers!$B$4/12),0) -> 1804.9215 | D13: =IF(SUM($C$3:C12)/Numbers!$E$3<Numbers!$B$10,12*Numbers!$E$7,0) -> 320.625 | E13: =12*Numbers!$B$15*(1-Numbers!$B$33)*(1+Numbers!$B$30)^('30 Year IRR'!A13-1)-('30 Year IRR'!B13+'30 Year IRR'!C13+'30 Year IRR'!D13+12*(Numbers!$E$8+Numbers!$E$9)*(1+Numbers!$B$30)^('30 Year IRR'!A13-1)+12*(1-Numbers!$B$33)*Numbers!$B$16*(1+Numbers!$B$30)^('30 Year IRR'!A13-1)+12*Numbers!$B$33*Numbers!$B$19*(1+Numbers!$B$30)^('30 Year IRR'!A13-1)) -> 7013.704 | F13: =Numbers!$B$35*('30 Year IRR'!E13+'30 Year IRR'!C13-IF(A13<27.5,Numbers!$E$14,0)) -> 1586.4746 | G13: =E13-F13 -> 5427.2294
A14: 11 | B14: =IF(A14<=Numbers!$B$5,Numbers!$E$4*(12*'30 Year IRR'!A14-1/(1+Numbers!$B$4/12)^(Numbers!$B$5*12-12*'30 Year IRR'!A14)*(1-1/(1+Numbers!$B$4/12)^(12*'30 Year IRR'!A14))/(Numbers!$B$4/12))-Numbers!$E$4*(12*'30 Year IRR'!A13-1/(1+Numbers!$B$4/12)^(Numbers!$B$5*12-12*'30 Year IRR'!A13)*(1-1/(1+Numbers!$B$4/12)^(12*'30 Year IRR'!A13))/(Numbers!$B$4/12)),0) -> 2179.7725 | C14: =IF(A14<=Numbers!$B$5,Numbers!$E$4*(1/(1+Numbers!$B$4/12))^(12*Numbers!$B$5-12*'30 Year IRR'!A14)*(1-1/(1+Numbers!$B$4/12)^(12*'30 Year IRR'!A14))/(Numbers!$B$4/12)-Numbers!$E$4*(1/(1+Numbers!$B$4/12))^(12*Numbers!$B$5-12*('30 Year IRR'!A14-1))*(1-1/(1+Numbers!$B$4/12)^(12*('30 Year IRR'!A14-1)))/(Numbers!$B$4/12),0) -> 1877.5209 | D14: =IF(SUM($C$3:C13)/Numbers!$E$3<Numbers!$B$10,12*Numbers!$E$7,0) -> 0 | E14: =12*Numbers!$B$15*(1-Numbers!$B$33)*(1+Numbers!$B$30)^('30 Year IRR'!A14-1)-('30 Year IRR'!B14+'30 Year IRR'!C14+'30 Year IRR'!D14+12*(Numbers!$E$8+Numbers!$E$9)*(1+Numbers!$B$30)^('30 Year IRR'!A14-1)+12*(1-Numbers!$B$33)*Numbers!$B$16*(1+Numbers!$B$30)^('30 Year IRR'!A14-1)+12*Numbers!$B$33*Numbers!$B$19*(1+Numbers!$B$30)^('30 Year IRR'!A14-1)) -> 7562.1614 | F14: =Numbers!$B$35*('30 Year IRR'!E14+'30 Year IRR'!C14-IF(A14<27.5,Numbers!$E$14,0)) -> 1741.7388 | G14: =E14-F14 -> 5820.4227
A15: 12 | B15: =IF(A15<=Numbers!$B$5,Numbers!$E$4*(12*'30 Year IRR'!A15-1/(1+Numbers!$B$4/12)^(Numbers!$B$5*12-12*'30 Year IRR'!A15)*(1-1/(1+Numbers!$B$4/12)^(12*'30 Year IRR'!A15))/(Numbers!$B$4/12))-Numbers!$E$4*(12*'30 Year IRR'!A14-1/(1+Numbers!$B$4/12)^(Numbers!$B$5*12-12*'30 Year IRR'!A14)*(1-1/(1+Numbers!$B$4/12)^(12*'30 Year IRR'!A14))/(Numbers!$B$4/12)),0) -> 2104.2529 | C15: =IF(A15<=Numbers!$B$5,Numbers!$E$4*(1/(1+Numbers!$B$4/12))^(12*Numbers!$B$5-12*'30 Year IRR'!A15)*(1-1/(1+Numbers!$B$4/12)^(12*'30 Year IRR'!A15))/(Numbers!$B$4/12)-Numbers!$E$4*(1/(1+Numbers!$B$4/12))^(12*Numbers!$B$5-12*('30 Year IRR'!A15-1))*(1-1/(1+Numbers!$B$4/12)^(12*('30 Year IRR'!A15-1)))/(Numbers!$B$4/12),0) -> 1953.0405 | D15: =IF(SUM($C$3:C14)/Numbers!$E$3<Numbers!$B$10,12*Numbers!$E$7,0) -> 0 | E15: =12*Numbers!$B$15*(1-Numbers!$B$33)*(1+Numbers!$B$30)^('30 Year IRR'!A15-1)-('30 Year IRR'!B15+'30 Year IRR'!C15+'30 Year IRR'!D15+12*(Numbers!$E$8+Numbers!$E$9)*(1+Numbers!$B$30)^('30 Year IRR'!A15-1)+12*(1-Numbers!$B$33)*Numbers!$B$16*(1+Numbers!$B$30)^('30 Year IRR'!A15-1)+12*Numbers!$B$33*Numbers!$B$19*(1+Numbers!$B$30)^('30 Year IRR'!A15-1)) -> 7794.5505 | F15: =Numbers!$B$35*('30 Year IRR'!E15+'30 Year IRR'!C15-IF(A15<27.5,Numbers!$E$14,0)) -> 1818.7159 | G15: =E15-F15 -> 5975.8346
A16: 13 | B16: =IF(A16<=Numbers!$B$5,Numbers!$E$4*(12*'30 Year IRR'!A16-1/(1+Numbers!$B$4/12)^(Numbers!$B$5*12-12*'30 Year IRR'!A16)*(1-1/(1+Numbers!$B$4/12)^(12*'30 Year IRR'!A16))/(Numbers!$B$4/12))-Numbers!$E$4*(12*'30 Year IRR'!A15-1/(1+Numbers!$B$4/12)^(Numbers!$B$5*12-12*'30 Year IRR'!A15)*(1-1/(1+Numbers!$B$4/12)^(12*'30 Year IRR'!A15))/(Numbers!$B$4/12)),0) -> 2025.6957 | C16: =IF(A16<=Numbers!$B$5,Numbers!$E$4*(1/(1+Numbers!$B$4/12))^(12*Numbers!$B$5-12*'30 Year IRR'!A16)*(1-1/(1+Numbers!$B$4/12)^(12*'30 Year IRR'!A16))/(Numbers!$B$4/12)-Numbers!$E$4*(1/(1+Numbers!$B$4/12))^(12*Numbers!$B$5-12*('30 Year IRR'!A16-1))*(1-1/(1+Numbers!$B$4/12)^(12*('30 Year IRR'!A16-1)))/(Numbers!$B$4/12),0) -> 2031.5976 | D16: =IF(SUM($C$3:C15)/Numbers!$E$3<Numbers!$B$10,12*Numbers!$E$7,0) -> 0 | E16: =12*Numbers!$B$15*(1-Numbers!$B$33)*(1+Numbers!$B$30)^('30 Year IRR'!A16-1)-('30 Year IRR'!B16+'30 Year IRR'!C16+'30 Year IRR'!D16+12*(Numbers!$E$8+Numbers!$E$9)*(1+Numbers!$B$30)^('30 Year IRR'!A16-1)+12*(1-Numbers!$B$33)*Numbers!$B$16*(1+Numbers!$B$30)^('30 Year IRR'!A16-1)+12*Numbers!$B$33*Numbers!$B$19*(1+Numbers!$B$30)^('30 Year IRR'!A16-1)) -> 8031.5874 | F16: =Numbers!$B$35*('30 Year IRR'!E16+'30 Year IRR'!C16-IF(A16<27.5,Numbers!$E$14,0)) -> 1897.6144 | G16: =E16-F16 -> 6133.973
... A22: 19 | B22: =IF(A22<=Numbers!$B$5,Numbers!$E$4*(12*'30 Year IRR'!A22-1/(1+Numbers!$B$4/12)^(Numbers!$B$5*12-12*'30 Year IRR'!A22)*(1-1/(1+Numbers!$B$4/12)^(12*'30 Year IRR'!A22))/(Numbers!$B$4/12))-Numbers!$E$4*(12*'30 Year IRR'!A21-1/(1+Numbers!$B$4/12)^(Numbers!$B$5*12-12*'30 Year IRR'!A21)*(1-1/(1+Numbers!$B$4/12)^(12*'30 Year IRR'!A21))/(Numbers!$B$4/12)),0) -> 1483.365 | C22: =IF(A22<=Numbers!$B$5,Numbers!$E$4*(1/(1+Numbers!$B$4/12))^(12*Numbers!$B$5-12*'30 Year IRR'!A22)*(1-1/(1+Numbers!$B$4/12)^(12*'30 Year IRR'!A22))/(Numbers!$B$4/12)-Numbers!$E$4*(1/(1+Numbers!$B$4/12))^(12*Numbers!$B$5-12*('30 Year IRR'!A22-1))*(1-1/(1+Numbers!$B$4/12)^(12*('30 Year IRR'!A22-1)))/(Numbers!$B$4/12),0) -> 2573.9284 | D22: =IF(SUM($C$3:C21)/Numbers!$E$3<Numbers!$B$10,12*Numbers!$E$7,0) -> 0 | E22: =12*Numbers!$B$15*(1-Numbers!$B$33)*(1+Numbers!$B$30)^('30 Year IRR'!A22-1)-('30 Year IRR'!B22+'30 Year IRR'!C22+'30 Year IRR'!D22+12*(Numbers!$E$8+Numbers!$E$9)*(1+Numbers!$B$30)^('30 Year IRR'!A22-1)+12*(1-Numbers!$B$33)*Numbers!$B$16*(1+Numbers!$B$30)^('30 Year IRR'!A22-1)+12*Numbers!$B$33*Numbers!$B$19*(1+Numbers!$B$30)^('30 Year IRR'!A22-1)) -> 9556.7499 | F22: =Numbers!$B$35*('30 Year IRR'!E22+'30 Year IRR'!C22-IF(A22<27.5,Numbers!$E$14,0)) -> 2414.4877 | G22: =E22-F22 -> 7142.2621
A23: 20 | B23: =IF(A23<=Numbers!$B$5,Numbers!$E$4*(12*'30 Year IRR'!A23-1/(1+Numbers!$B$4/12)^(Numbers!$B$5*12-12*'30 Year IRR'!A23)*(1-1/(1+Numbers!$B$4/12)^(12*'30 Year IRR'!A23))/(Numbers!$B$4/12))-Numbers!$E$4*(12*'30 Year IRR'!A22-1/(1+Numbers!$B$4/12)^(Numbers!$B$5*12-12*'30 Year IRR'!A22)*(1-1/(1+Numbers!$B$4/12)^(12*'30 Year IRR'!A22))/(Numbers!$B$4/12)),0) -> 1379.8338 | C23: =IF(A23<=Numbers!$B$5,Numbers!$E$4*(1/(1+Numbers!$B$4/12))^(12*Numbers!$B$5-12*'30 Year IRR'!A23)*(1-1/(1+Numbers!$B$4/12)^(12*'30 Year IRR'!A23))/(Numbers!$B$4/12)-Numbers!$E$4*(1/(1+Numbers!$B$4/12))^(12*Numbers!$B$5-12*('30 Year IRR'!A23-1))*(1-1/(1+Numbers!$B$4/12)^(12*('30 Year IRR'!A23-1)))/(Numbers!$B$4/12),0) -> 2677.4596 | D23: =IF(SUM($C$3:C22)/Numbers!$E$3<Numbers!$B$10,12*Numbers!$E$7,0) -> 0 | E23: =12*Numbers!$B$15*(1-Numbers!$B$33)*(1+Numbers!$B$30)^('30 Year IRR'!A23-1)-('30 Year IRR'!B23+'30 Year IRR'!C23+'30 Year IRR'!D23+12*(Numbers!$E$8+Numbers!$E$9)*(1+Numbers!$B$30)^('30 Year IRR'!A23-1)+12*(1-Numbers!$B$33)*Numbers!$B$16*(1+Numbers!$B$30)^('30 Year IRR'!A23-1)+12*Numbers!$B$33*Numbers!$B$19*(1+Numbers!$B$30)^('30 Year IRR'!A23-1)) -> 9829.0307 | F23: =Numbers!$B$35*('30 Year IRR'!E23+'30 Year IRR'!C23-IF(A23<27.5,Numbers!$E$14,0)) -> 2508.4408 | G23: =E23-F23+D31 -> 86830.111
C25: Sale Price: | D25: =(1+Numbers!$B$31)^20*(Numbers!B3+Numbers!B8) -> 144488.9 | F25: Lifetime Cash: | G25: =SUM(G4:G23)-D31 -> 111557.31
C26: Adj Sale Price: | D26: =(1-Numbers!B23)*'20 Year IRR'!D25-Numbers!B24 -> 132819.56
C27: Depreciated Basis: | D27: =Numbers!E13-20*Numbers!E14 -> 33545.455
C28: Capital Gains: | D28: =(D26-Numbers!E13)*Numbers!B25 -> 7472.9347
C29: Depr Recapture: | D29: =Numbers!B26*(Numbers!E13-'20 Year IRR'!D27) -> 12363.636
C30: Principal Owed: | D30: =Numbers!E3-SUM(C4:C23) -> 33473.473
C31: Sale Profit: | D31: =D26-D28-D29-D30 -> 79509.521
C33: LIFETIME IRR: | D33: =IRR(G3:G23) -> 0.35284057

Sheet 15 Year IRR
A1: Year | B1: Interest Paid | C1: Principal Paid | D1: PMI Paid | E1: Gross Income | F1: Income Taxes | G1: Net Cash Flow
A3: 0 | G3: =-Numbers!E23 -> -11750
A4: 1 | B4: =IF(A4<=Numbers!$B$5,Numbers!$E$4*(12*'30 Year IRR'!A4-1/(1+Numbers!$B$4/12)^(Numbers!$B$5*12-12*'30 Year IRR'!A4)*(1-1/(1+Numbers!$B$4/12)^(12*'30 Year IRR'!A4))/(Numbers!$B$4/12))-Numbers!$E$4*(12*'30 Year IRR'!A3-1/(1+Numbers!$B$4/12)^(Numbers!$B$5*12-12*'30 Year IRR'!A3)*(1-1/(1+Numbers!$B$4/12)^(12*'30 Year IRR'!A3))/(Numbers!$B$4/12)),0) -> 2791.6243 | C4: =IF(A4<=Numbers!$B$5,Numbers!$E$4*(1/(1+Numbers!$B$4/12))^(12*Numbers!$B$5-12*'30 Year IRR'!A4)*(1-1/(1+Numbers!$B$4/12)^(12*'30 Year IRR'!A4))/(Numbers!$B$4/12)-Numbers!$E$4*(1/(1+Numbers!$B$4/12))^(12*Numbers!$B$5-12*('30 Year IRR'!A4-1))*(1-1/(1+Numbers!$B$4/12)^(12*('30 Year IRR'!A4-1)))/(Numbers!$B$4/12),0) -> 1265.6691 | D4: =IF(SUM($C$3:C3)/Numbers!$E$3<Numbers!$B$10,12*Numbers!$E$7,0) -> 320.625 | E4: =12*Numbers!$B$15*(1-Numbers!$B$33)*(1+Numbers!$B$30)^('30 Year IRR'!A4-1)-('30 Year IRR'!B4+'30 Year IRR'!C4+'30 Year IRR'!D4+12*(Numbers!$E$8+Numbers!$E$9)*(1+Numbers!$B$30)^('30 Year IRR'!A4-1)+12*(1-Numbers!$B$33)*Numbers!$B$16*(1+Numbers!$B$30)^('30 Year IRR'!A4-1)+12*Numbers!$B$33*Numbers!$B$19*(1+Numbers!$B$30)^('30 Year IRR'!A4-1))-Numbers!B11*Numbers!B15 -> 2754.0816 | F4: =Numbers!$B$35*('30 Year IRR'!E4+'30 Year IRR'!C4-IF(A4<27.5,Numbers!$E$14,0)) -> 386.75587 | G4: =E4-F4 -> 2367.3258
A5: 2 | B5: =IF(A5<=Numbers!$B$5,Numbers!$E$4*(12*'30 Year IRR'!A5-1/(1+Numbers!$B$4/12)^(Numbers!$B$5*12-12*'30 Year IRR'!A5)*(1-1/(1+Numbers!$B$4/12)^(12*'30 Year IRR'!A5))/(Numbers!$B$4/12))-Numbers!$E$4*(12*'30 Year IRR'!A4-1/(1+Numbers!$B$4/12)^(Numbers!$B$5*12-12*'30 Year IRR'!A4)*(1-1/(1+Numbers!$B$4/12)^(12*'30 Year IRR'!A4))/(Numbers!$B$4/12)),0) -> 2740.7152 | C5: =IF(A5<=Numbers!$B$5,Numbers!$E$4*(1/(1+Numbers!$B$4/12))^(12*Numbers!$B$5-12*'30 Year IRR'!A5)*(1-1/(1+Numbers!$B$4/12)^(12*'30 Year IRR'!A5))/(Numbers!$B$4/12)-Numbers!$E$4*(1/(1+Numbers!$B$4/12))^(12*Numbers!$B$5-12*('30 Year IRR'!A5-1))*(1-1/(1+Numbers!$B$4/12)^(12*('30 Year IRR'!A5-1)))/(Numbers!$B$4/12),0) -> 1316.5781 | D5: =IF(SUM($C$3:C4)/Numbers!$E$3<Numbers!$B$10,12*Numbers!$E$7,0) -> 320.625 | E5: =12*Numbers!$B$15*(1-Numbers!$B$33)*(1+Numbers!$B$30)^('30 Year IRR'!A5-1)-('30 Year IRR'!B5+'30 Year IRR'!C5+'30 Year IRR'!D5+12*(Numbers!$E$8+Numbers!$E$9)*(1+Numbers!$B$30)^('30 Year IRR'!A5-1)+12*(1-Numbers!$B$33)*Numbers!$B$16*(1+Numbers!$B$30)^('30 Year IRR'!A5-1)+12*Numbers!$B$33*Numbers!$B$19*(1+Numbers!$B$30)^('30 Year IRR'!A5-1)) -> 5344.7216 | F5: =Numbers!$B$35*('30 Year IRR'!E5+'30 Year IRR'!C5-IF(A5<27.5,Numbers!$E$14,0)) -> 1047.1431 | G5: =E5-F5 -> 4297.5785
A6: 3 | B6: =IF(A6<=Numbers!$B$5,Numbers!$E$4*(12*'30 Year IRR'!A6-1/(1+Numbers!$B$4/12)^(Numbers!$B$5*12-12*'30 Year IRR'!A6)*(1-1/(1+Numbers!$B$4/12)^(12*'30 Year IRR'!A6))/(Numbers!$B$4/12))-Numbers!$E$4*(12*'30 Year IRR'!A5-1/(1+Numbers!$B$4/12)^(Numbers!$B$5*12-12*'30 Year IRR'!A5)*(1-1/(1+Numbers!$B$4/12)^(12*'30 Year IRR'!A5))/(Numbers!$B$4/12)),0) -> 2687.7585 | C6: =IF(A6<=Numbers!$B$5,Numbers!$E$4*(1/(1+Numbers!$B$4/12))^(12*Numbers!$B$5-12*'30 Year IRR'!A6)*(1-1/(1+Numbers!$B$4/12)^(12*'30 Year IRR'!A6))/(Numbers!$B$4/12)-Numbers!$E$4*(1/(1+Numbers!$B$4/12))^(12*Numbers!$B$5-12*('30 Year IRR'!A6-1))*(1-1/(1+Numbers!$B$4/12)^(12*('30 Year IRR'!A6-1)))/(Numbers!$B$4/12),0) -> 1369.5349 | D6: =IF(SUM($C$3:C5)/Numbers!$E$3<Numbers!$B$10,12*Numbers!$E$7,0) -> 320.625 | E6: =12*Numbers!$B$15*(1-Numbers!$B$33)*(1+Numbers!$B$30)^('30 Year IRR'!A6-1)-('30 Year IRR'!B6+'30 Year IRR'!C6+'30 Year IRR'!D6+12*(Numbers!$E$8+Numbers!$E$9)*(1+Numbers!$B$30)^('30 Year IRR'!A6-1)+12*(1-Numbers!$B$33)*Numbers!$B$16*(1+Numbers!$B$30)^('30 Year IRR'!A6-1)+12*Numbers!$B$33*Numbers!$B$19*(1+Numbers!$B$30)^('30 Year IRR'!A6-1)) -> 5539.1744 | F6: =Numbers!$B$35*('30 Year IRR'!E6+'30 Year IRR'!C6-IF(A6<27.5,Numbers!$E$14,0)) -> 1108.9955 | G6: =E6-F6 -> 4430.1789
A7: 4 | B7: =IF(A7<=Numbers!$B$5,Numbers!$E$4*(12*'30 Year IRR'!A7-1/(1+Numbers!$B$4/12)^(Numbers!$B$5*12-12*'30 Year IRR'!A7)*(1-1/(1+Numbers!$B$4/12)^(12*'30 Year IRR'!A7))/(Numbers!$B$4/12))-Numbers!$E$4*(12*'30 Year IRR'!A6-1/(1+Numbers!$B$4/12)^(Numbers!$B$5*12-12*'30 Year IRR'!A6)*(1-1/(1+Numbers!$B$4/12)^(12*'30 Year IRR'!A6))/(Numbers!$B$4/12)),0) -> 2632.6717 | C7: =IF(A7<=Numbers!$B$5,Numbers!$E$4*(1/(1+Numbers!$B$4/12))^(12*Numbers!$B$5-12*'30 Year IRR'!A7)*(1-1/(1+Numbers!$B$4/12)^(12*'30 Year IRR'!A7))/(Numbers!$B$4/12)-Numbers!$E$4*(1/(1+Numbers!$B$4/12))^(12*Numbers!$B$5-12*('30 Year IRR'!A7-1))*(1-1/(1+Numbers!$B$4/12)^(12*('30 Year IRR'!A7-1)))/(Numbers!$B$4/12),0) -> 1424.6217 | D7: =IF(SUM($C$3:C6)/Numbers!$E$3<Numbers!$B$10,12*Numbers!$E$7,0) -> 320.625 | E7: =12*Numbers!$B$15*(1-Numbers!$B$33)*(1+Numbers!$B$30)^('30 Year IRR'!A7-1)-('30 Year IRR'!B7+'30 Year IRR'!C7+'30 Year IRR'!D7+12*(Numbers!$E$8+Numbers!$E$9)*(1+Numbers!$B$30)^('30 Year IRR'!A7-1)+12*(1-Numbers!$B$33)*Numbers!$B$16*(1+Numbers!$B$30)^('30 Year IRR'!A7-1)+12*Numbers!$B$33*Numbers!$B$19*(1+Numbers!$B$30)^('30 Year IRR'!A7-1)) -> 5737.5163 | F7: =Numbers!$B$35*('30 Year IRR'!E7+'30 Year IRR'!C7-IF(A7<27.5,Numbers!$E$14,0)) -> 1172.3527 | G7: =E7-F7 -> 4565.1636
A8: 5 | B8: =IF(A8<=Numbers!$B$5,Numbers!$E$4*(12*'30 Year IRR'!A8-1/(1+Numbers!$B$4/12)^(Numbers!$B$5*12-12*'30 Year IRR'!A8)*(1-1/(1+Numbers!$B$4/12)^(12*'30 Year IRR'!A8))/(Numbers!$B$4/12))-Numbers!$E$4*(12*'30 Year IRR'!A7-1/(1+Numbers!$B$4/12)^(Numbers!$B$5*12-12*'30 Year IRR'!A7)*(1-1/(1+Numbers!$B$4/12)^(12*'30 Year IRR'!A7))/(Numbers!$B$4/12)),0) -> 2575.3691 | C8: =IF(A8<=Numbers!$B$5,Numbers!$E$4*(1/(1+Numbers!$B$4/12))^(12*Numbers!$B$5-12*'30 Year IRR'!A8)*(1-1/(1+Numbers!$B$4/12)^(12*'30 Year IRR'!A8))/(Numbers!$B$4/12)-Numbers!$E$4*(1/(1+Numbers!$B$4/12))^(12*Numbers!$B$5-12*('30 Year IRR'!A8-1))*(1-1/(1+Numbers!$B$4/12)^(12*('30 Year IRR'!A8-1)))/(Numbers!$B$4/12),0) -> 1481.9243 | D8: =IF(SUM($C$3:C7)/Numbers!$E$3<Numbers!$B$10,12*Numbers!$E$7,0) -> 320.625 | E8: =12*Numbers!$B$15*(1-Numbers!$B$33)*(1+Numbers!$B$30)^('30 Year IRR'!A8-1)-('30 Year IRR'!B8+'30 Year IRR'!C8+'30 Year IRR'!D8+12*(Numbers!$E$8+Numbers!$E$9)*(1+Numbers!$B$30)^('30 Year IRR'!A8-1)+12*(1-Numbers!$B$33)*Numbers!$B$16*(1+Numbers!$B$30)^('30 Year IRR'!A8-1)+12*Numbers!$B$33*Numbers!$B$19*(1+Numbers!$B$30)^('30 Year IRR'!A8-1)) -> 5939.825 | F8: =Numbers!$B$35*('30 Year IRR'!E8+'30 Year IRR'!C8-IF(A8<27.5,Numbers!$E$14,0)) -> 1237.2555 | G8: =E8-F8 -> 4702.5695
A9: 6 | B9: =IF(A9<=Numbers!$B$5,Numbers!$E$4*(12*'30 Year IRR'!A9-1/(1+Numbers!$B$4/12)^(Numbers!$B$5*12-12*'30 Year IRR'!A9)*(1-1/(1+Numbers!$B$4/12)^(12*'30 Year IRR'!A9))/(Numbers!$B$4/12))-Numbers!$E$4*(12*'30 Year IRR'!A8-1/(1+Numbers!$B$4/12)^(Numbers!$B$5*12-12*'30 Year IRR'!A8)*(1-1/(1+Numbers!$B$4/12)^(12*'30 Year IRR'!A8))/(Numbers!$B$4/12)),0) -> 2515.7616 | C9: =IF(A9<=Numbers!$B$5,Numbers!$E$4*(1/(1+Numbers!$B$4/12))^(12*Numbers!$B$5-12*'30 Year IRR'!A9)*(1-1/(1+Numbers!$B$4/12)^(12*'30 Year IRR'!A9))/(Numbers!$B$4/12)-Numbers!$E$4*(1/(1+Numbers!$B$4/12))^(12*Numbers!$B$5-12*('30 Year IRR'!A9-1))*(1-1/(1+Numbers!$B$4/12)^(12*('30 Year IRR'!A9-1)))/(Numbers!$B$4/12),0) -> 1541.5318 | D9: =IF(SUM($C$3:C8)/Numbers!$E$3<Numbers!$B$10,12*Numbers!$E$7,0) -> 320.625 | E9: =12*Numbers!$B$15*(1-Numbers!$B$33)*(1+Numbers!$B$30)^('30 Year IRR'!A9-1)-('30 Year IRR'!B9+'30 Year IRR'!C9+'30 Year IRR'!D9+12*(Numbers!$E$8+Numbers!$E$9)*(1+Numbers!$B$30)^('30 Year IRR'!A9-1)+12*(1-Numbers!$B$33)*Numbers!$B$16*(1+Numbers!$B$30)^('30 Year IRR'!A9-1)+12*Numbers!$B$33*Numbers!$B$19*(1+Numbers!$B$30)^('30 Year IRR'!A9-1)) -> 6146.1798 | F9: =Numbers!$B$35*('30 Year IRR'!E9+'30 Year IRR'!C9-IF(A9<27.5,Numbers!$E$14,0)) -> 1303.7461 | G9: =E9-F9 -> 4842.4338
A10: 7 | B10: =IF(A10<=Numbers!$B$5,Numbers!$E$4*(12*'30 Year IRR'!A10-1/(1+Numbers!$B$4/12)^(Numbers!$B$5*12-12*'30 Year IRR'!A10)*(1-1/(1+Numbers!$B$4/12)^(12*'30 Year IRR'!A10))/(Numbers!$B$4/12))-Numbers!$E$4*(12*'30 Year IRR'!A9-1/(1+Numbers!$B$4/12)^(Numbers!$B$5*12-12*'30 Year IRR'!A9)*(1-1/(1+Numbers!$B$4/12)^(12*'30 Year IRR'!A9))/(Numbers!$B$4/12)),0) -> 2453.7565 | C10: =IF(A10<=Numbers!$B$5,Numbers!$E$4*(1/(1+Numbers!$B$4/12))^(12*Numbers!$B$5-12*'30 Year IRR'!A10)*(1-1/(1+Numbers!$B$4/12)^(12*'30 Year IRR'!A10))/(Numbers!$B$4/12)-Numbers!$E$4*(1/(1+Numbers!$B$4/12))^(12*Numbers!$B$5-12*('30 Year IRR'!A10-1))*(1-1/(1+Numbers!$B$4/12)^(12*('30 Year IRR'!A10-1)))/(Numbers!$B$4/12),0) -> 1603.5368 | D10: =IF(SUM($C$3:C9)/Numbers!$E$3<Numbers!$B$10,12*Numbers!$E$7,0) -> 320.625 | E10: =12*Numbers!$B$15*(1-Numbers!$B$33)*(1+Numbers!$B$30)^('30 Year IRR'!A10-1)-('30 Year IRR'!B10+'30 Year IRR'!C10+'30 Year IRR'!D10+12*(Numbers!$E$8+Numbers!$E$9)*(1+Numbers!$B$30)^('30 Year IRR'!A10-1)+12*(1-Numbers!$B$33)*Numbers!$B$16*(1+Numbers!$B$30)^('30 Year IRR'!A10-1)+12*Numbers!$B$33*Numbers!$B$19*(1+Numbers!$B$30)^('30 Year IRR'!A10-1)) -> 6356.6618 | F10: =Numbers!$B$35*('30 Year IRR'!E10+'30 Year IRR'!C10-IF(A10<27.5,Numbers!$E$14,0)) -> 1371.8678 | G10: =E10-F10 -> 4984.794
A11: 8 | B11: =IF(A11<=Numbers!$B$5,Numbers!$E$4*(12*'30 Year IRR'!A11-1/(1+Numbers!$B$4/12)^(Numbers!$B$5*12-12*'30 Year IRR'!A11)*(1-1/(1+Numbers!$B$4/12)^(12*'30 Year IRR'!A11))/(Numbers!$B$4/12))-Numbers!$E$4*(12*'30 Year IRR'!A10-1/(1+Numbers!$B$4/12)^(Numbers!$B$5*12-12*'30 Year IRR'!A10)*(1-1/(1+Numbers!$B$4/12)^(12*'30 Year IRR'!A10))/(Numbers!$B$4/12)),0) -> 2389.2574 | C11: =IF(A11<=Numbers!$B$5,Numbers!$E$4*(1/(1+Numbers!$B$4/12))^(12*Numbers!$B$5-12*'30 Year IRR'!A11)*(1-1/(1+Numbers!$B$4/12)^(12*'30 Year IRR'!A11))/(Numbers!$B$4/12)-Numbers!$E$4*(1/(1+Numbers!$B$4/12))^(12*Numbers!$B$5-12*('30 Year IRR'!A11-1))*(1-1/(1+Numbers!$B$4/12)^(12*('30 Year IRR'!A11-1)))/(Numbers!$B$4/12),0) -> 1668.0359 | D11: =IF(SUM($C$3:C10)/Numbers!$E$3<Numbers!$B$10,12*Numbers!$E$7,0) -> 320.625 | E11: =12*Numbers!$B$15*(1-Numbers!$B$33)*(1+Numbers!$B$30)^('30 Year IRR'!A11-1)-('30 Year IRR'!B11+'30 Year IRR'!C11+'30 Year IRR'!D11+12*(Numbers!$E$8+Numbers!$E$9)*(1+Numbers!$B$30)^('30 Year IRR'!A11-1)+12*(1-Numbers!$B$33)*Numbers!$B$16*(1+Numbers!$B$30)^('30 Year IRR'!A11-1)+12*Numbers!$B$33*Numbers!$B$19*(1+Numbers!$B$30)^('30 Year IRR'!A11-1)) -> 6571.3534 | F11: =Numbers!$B$35*('30 Year IRR'!E11+'30 Year IRR'!C11-IF(A11<27.5,Numbers!$E$14,0)) -> 1441.6655 | G11: =E11-F11 -> 5129.6879
A12: 9 | B12: =IF(A12<=Numbers!$B$5,Numbers!$E$4*(12*'30 Year IRR'!A12-1/(1+Numbers!$B$4/12)^(Numbers!$B$5*12-12*'30 Year IRR'!A12)*(1-1/(1+Numbers!$B$4/12)^(12*'30 Year IRR'!A12))/(Numbers!$B$4/12))-Numbers!$E$4*(12*'30 Year IRR'!A11-1/(1+Numbers!$B$4/12)^(Numbers!$B$5*12-12*'30 Year IRR'!A11)*(1-1/(1+Numbers!$B$4/12)^(12*'30 Year IRR'!A11))/(Numbers!$B$4/12)),0) -> 2322.164 | C12: =IF(A12<=Numbers!$B$5,Numbers!$E$4*(1/(1+Numbers!$B$4/12))^(12*Numbers!$B$5-12*'30 Year IRR'!A12)*(1-1/(1+Numbers!$B$4/12)^(12*'30 Year IRR'!A12))/(Numbers!$B$4/12)-Numbers!$E$4*(1/(1+Numbers!$B$4/12))^(12*Numbers!$B$5-12*('30 Year IRR'!A12-1))*(1-1/(1+Numbers!$B$4/12)^(12*('30 Year IRR'!A12-1)))/(Numbers!$B$4/12),0) -> 1735.1294 | D12: =IF(SUM($C$3:C11)/Numbers!$E$3<Numbers!$B$10,12*Numbers!$E$7,0) -> 320.625 | E12: =12*Numbers!$B$15*(1-Numbers!$B$33)*(1+Numbers!$B$30)^('30 Year IRR'!A12-1)-('30 Year IRR'!B12+'30 Year IRR'!C12+'30 Year IRR'!D12+12*(Numbers!$E$8+Numbers!$E$9)*(1+Numbers!$B$30)^('30 Year IRR'!A12-1)+12*(1-Numbers!$B$33)*Numbers!$B$16*(1+Numbers!$B$30)^('30 Year IRR'!A12-1)+12*Numbers!$B$33*Numbers!$B$19*(1+Numbers!$B$30)^('30 Year IRR'!A12-1)) -> 6790.3389 | F12: =Numbers!$B$35*('30 Year IRR'!E12+'30 Year IRR'!C12-IF(A12<27.5,Numbers!$E$14,0)) -> 1513.1852 | G12: =E12-F12 -> 5277.1536
A13: 10 | B13: =IF(A13<=Numbers!$B$5,Numbers!$E$4*(12*'30 Year IRR'!A13-1/(1+Numbers!$B$4/12)^(Numbers!$B$5*12-12*'30 Year IRR'!A13)*(1-1/(1+Numbers!$B$4/12)^(12*'30 Year IRR'!A13))/(Numbers!$B$4/12))-Numbers!$E$4*(12*'30 Year IRR'!A12-1/(1+Numbers!$B$4/12)^(Numbers!$B$5*12-12*'30 Year IRR'!A12)*(1-1/(1+Numbers!$B$4/12)^(12*'30 Year IRR'!A12))/(Numbers!$B$4/12)),0) -> 2252.3719 | C13: =IF(A13<=Numbers!$B$5,Numbers!$E$4*(1/(1+Numbers!$B$4/12))^(12*Numbers!$B$5-12*'30 Year IRR'!A13)*(1-1/(1+Numbers!$B$4/12)^(12*'30 Year IRR'!A13))/(Numbers!$B$4/12)-Numbers!$E$4*(1/(1+Numbers!$B$4/12))^(12*Numbers!$B$5-12*('30 Year IRR'!A13-1))*(1-1/(1+Numbers!$B$4/12)^(12*('30 Year IRR'!A13-1)))/(Numbers!$B$4/12),0) -> 1804.9215 | D13: =IF(SUM($C$3:C12)/Numbers!$E$3<Numbers!$B$10,12*Numbers!$E$7,0) -> 320.625 | E13: =12*Numbers!$B$15*(1-Numbers!$B$33)*(1+Numbers!$B$30)^('30 Year IRR'!A13-1)-('30 Year IRR'!B13+'30 Year IRR'!C13+'30 Year IRR'!D13+12*(Numbers!$E$8+Numbers!$E$9)*(1+Numbers!$B$30)^('30 Year IRR'!A13-1)+12*(1-Numbers!$B$33)*Numbers!$B$16*(1+Numbers!$B$30)^('30 Year IRR'!A13-1)+12*Numbers!$B$33*Numbers!$B$19*(1+Numbers!$B$30)^('30 Year IRR'!A13-1)) -> 7013.704 | F13: =Numbers!$B$35*('30 Year IRR'!E13+'30 Year IRR'!C13-IF(A13<27.5,Numbers!$E$14,0)) -> 1586.4746 | G13: =E13-F13 -> 5427.2294
A14: 11 | B14: =IF(A14<=Numbers!$B$5,Numbers!$E$4*(12*'30 Year IRR'!A14-1/(1+Numbers!$B$4/12)^(Numbers!$B$5*12-12*'30 Year IRR'!A14)*(1-1/(1+Numbers!$B$4/12)^(12*'30 Year IRR'!A14))/(Numbers!$B$4/12))-Numbers!$E$4*(12*'30 Year IRR'!A13-1/(1+Numbers!$B$4/12)^(Numbers!$B$5*12-12*'30 Year IRR'!A13)*(1-1/(1+Numbers!$B$4/12)^(12*'30 Year IRR'!A13))/(Numbers!$B$4/12)),0) -> 2179.7725 | C14: =IF(A14<=Numbers!$B$5,Numbers!$E$4*(1/(1+Numbers!$B$4/12))^(12*Numbers!$B$5-12*'30 Year IRR'!A14)*(1-1/(1+Numbers!$B$4/12)^(12*'30 Year IRR'!A14))/(Numbers!$B$4/12)-Numbers!$E$4*(1/(1+Numbers!$B$4/12))^(12*Numbers!$B$5-12*('30 Year IRR'!A14-1))*(1-1/(1+Numbers!$B$4/12)^(12*('30 Year IRR'!A14-1)))/(Numbers!$B$4/12),0) -> 1877.5209 | D14: =IF(SUM($C$3:C13)/Numbers!$E$3<Numbers!$B$10,12*Numbers!$E$7,0) -> 0 | E14: =12*Numbers!$B$15*(1-Numbers!$B$33)*(1+Numbers!$B$30)^('30 Year IRR'!A14-1)-('30 Year IRR'!B14+'30 Year IRR'!C14+'30 Year IRR'!D14+12*(Numbers!$E$8+Numbers!$E$9)*(1+Numbers!$B$30)^('30 Year IRR'!A14-1)+12*(1-Numbers!$B$33)*Numbers!$B$16*(1+Numbers!$B$30)^('30 Year IRR'!A14-1)+12*Numbers!$B$33*Numbers!$B$19*(1+Numbers!$B$30)^('30 Year IRR'!A14-1)) -> 7562.1614 | F14: =Numbers!$B$35*('30 Year IRR'!E14+'30 Year IRR'!C14-IF(A14<27.5,Numbers!$E$14,0)) -> 1741.7388 | G14: =E14-F14 -> 5820.4227
A15: 12 | B15: =IF(A15<=Numbers!$B$5,Numbers!$E$4*(12*'30 Year IRR'!A15-1/(1+Numbers!$B$4/12)^(Numbers!$B$5*12-12*'30 Year IRR'!A15)*(1-1/(1+Numbers!$B$4/12)^(12*'30 Year IRR'!A15))/(Numbers!$B$4/12))-Numbers!$E$4*(12*'30 Year IRR'!A14-1/(1+Numbers!$B$4/12)^(Numbers!$B$5*12-12*'30 Year IRR'!A14)*(1-1/(1+Numbers!$B$4/12)^(12*'30 Year IRR'!A14))/(Numbers!$B$4/12)),0) -> 2104.2529 | C15: =IF(A15<=Numbers!$B$5,Numbers!$E$4*(1/(1+Numbers!$B$4/12))^(12*Numbers!$B$5-12*'30 Year IRR'!A15)*(1-1/(1+Numbers!$B$4/12)^(12*'30 Year IRR'!A15))/(Numbers!$B$4/12)-Numbers!$E$4*(1/(1+Numbers!$B$4/12))^(12*Numbers!$B$5-12*('30 Year IRR'!A15-1))*(1-1/(1+Numbers!$B$4/12)^(12*('30 Year IRR'!A15-1)))/(Numbers!$B$4/12),0) -> 1953.0405 | D15: =IF(SUM($C$3:C14)/Numbers!$E$3<Numbers!$B$10,12*Numbers!$E$7,0) -> 0 | E15: =12*Numbers!$B$15*(1-Numbers!$B$33)*(1+Numbers!$B$30)^('30 Year IRR'!A15-1)-('30 Year IRR'!B15+'30 Year IRR'!C15+'30 Year IRR'!D15+12*(Numbers!$E$8+Numbers!$E$9)*(1+Numbers!$B$30)^('30 Year IRR'!A15-1)+12*(1-Numbers!$B$33)*Numbers!$B$16*(1+Numbers!$B$30)^('30 Year IRR'!A15-1)+12*Numbers!$B$33*Numbers!$B$19*(1+Numbers!$B$30)^('30 Year IRR'!A15-1)) -> 7794.5505 | F15: =Numbers!$B$35*('30 Year IRR'!E15+'30 Year IRR'!C15-IF(A15<27.5,Numbers!$E$14,0)) -> 1818.7159 | G15: =E15-F15 -> 5975.8346
A16: 13 | B16: =IF(A16<=Numbers!$B$5,Numbers!$E$4*(12*'30 Year IRR'!A16-1/(1+Numbers!$B$4/12)^(Numbers!$B$5*12-12*'30 Year IRR'!A16)*(1-1/(1+Numbers!$B$4/12)^(12*'30 Year IRR'!A16))/(Numbers!$B$4/12))-Numbers!$E$4*(12*'30 Year IRR'!A15-1/(1+Numbers!$B$4/12)^(Numbers!$B$5*12-12*'30 Year IRR'!A15)*(1-1/(1+Numbers!$B$4/12)^(12*'30 Year IRR'!A15))/(Numbers!$B$4/12)),0) -> 2025.6957 | C16: =IF(A16<=Numbers!$B$5,Numbers!$E$4*(1/(1+Numbers!$B$4/12))^(12*Numbers!$B$5-12*'30 Year IRR'!A16)*(1-1/(1+Numbers!$B$4/12)^(12*'30 Year IRR'!A16))/(Numbers!$B$4/12)-Numbers!$E$4*(1/(1+Numbers!$B$4/12))^(12*Numbers!$B$5-12*('30 Year IRR'!A16-1))*(1-1/(1+Numbers!$B$4/12)^(12*('30 Year IRR'!A16-1)))/(Numbers!$B$4/12),0) -> 2031.5976 | D16: =IF(SUM($C$3:C15)/Numbers!$E$3<Numbers!$B$10,12*Numbers!$E$7,0) -> 0 | E16: =12*Numbers!$B$15*(1-Numbers!$B$33)*(1+Numbers!$B$30)^('30 Year IRR'!A16-1)-('30 Year IRR'!B16+'30 Year IRR'!C16+'30 Year IRR'!D16+12*(Numbers!$E$8+Numbers!$E$9)*(1+Numbers!$B$30)^('30 Year IRR'!A16-1)+12*(1-Numbers!$B$33)*Numbers!$B$16*(1+Numbers!$B$30)^('30 Year IRR'!A16-1)+12*Numbers!$B$33*Numbers!$B$19*(1+Numbers!$B$30)^('30 Year IRR'!A16-1)) -> 8031.5874 | F16: =Numbers!$B$35*('30 Year IRR'!E16+'30 Year IRR'!C16-IF(A16<27.5,Numbers!$E$14,0)) -> 1897.6144 | G16: =E16-F16 -> 6133.973
